Workbook

Sheet Cover
B4: 美股板塊估值地圖 & 低估板塊龍頭選股分析
B6: US Sector Valuation Map & Value-Sector Leaders: 5-Year Buffett-Lens Stock Selection
B9: 數據截至：2026-10-09 美股收盤（LongBridge OpenAPI）｜板塊估值：FactSet Earnings Insight（2026-10-09）
B10: 覆蓋：GICS 11 大板塊 → 4 個低估/低估值板塊 → 12 家龍頭（每板塊市值前 3）→ 最終 5+1 檔 5 年期組合
B13: 目錄 / Contents
B14: 1. Summary — 結論摘要與最終組合
B15: 2. Sector_Map — 11 大板塊 Forward P/E vs 5Y/10Y 均值、盈利增速、低估/高估判定
B16: 3. Methodology — 各板塊估值錨、P/E 失真點、板塊估值算法合理性評估
B17: 4. Competition — 板塊內部競爭方式、集中度、護城河來源
B18: 5. Macro — 宏觀儀表板 + 個股宏觀敏感度矩陣
B19: 6. Comps — 12 家龍頭可比估值表（可重算）
B20: 7. Financials — FY2020–FY2025 財務數據（LongBridge）
... B29: 免責聲明：本工作簿僅供研究與教育用途，不構成任何投資建議或買賣邀約。所有估值依賴公開數據與主觀假設，可能有誤；投資前請自行核實並諮詢持牌顧問。

Sheet Summary
A1: 結論摘要 Executive Summary
A2: 數據截至 2026-10-09；所有數字連結至對應工作表，可隨假設重算。
A4: 一、核心結論
B5: 1) 大盤：S&P 500 Fwd P/E 19.1x = 10Y 均值，但 Trailing 26.0x 偏高；盈利動能極強（Q3E +29.6%、CY26E +32.7%），CY27 放緩至 +15.8%。整體「合理偏貴」，選股重於擇時。
B6: 2) 板塊：相對 10Y 均值最低估——公用事業(−10.6%)、房地產(−10.2%)、原材料(−6.7%)；最高估——能源(+22.7%，盈利頂部陷阱)、工業(+14%)、醫療(+10%，LLY 拉高)。
B7: 3) 宏觀：伊朗衝突推高油價(Q3 均價 $85.7)與 CPI(3.4%)，Fed 9 月加息至 3.75–4.00%。利率敏感板塊（公用、REIT）被錯殺，但「高利率更久」仍是主要風險。
B8: 4) 估值方法：板塊 P/E 只能做首輪篩選。REIT 要看 P/FFO（WELL GAAP P/E 105x vs P/FFO 35x）、銀行看 P/B-ROE、礦業看中週期價格，否則會誤判。
B9: 5) 個股：12 家龍頭中，LIN 是唯一「質量頂級 + 倍數處 5 年低位」的組合（但 DCF 顯示市場已隱含 ~5% 永續增長，屬合理價而非深度價值）；BRK.B、V、JPM、PLD 屬「合理價格買卓越公司」；NEE 最便宜但風險最高；WELL/EQIX 好公司但太貴；NEM/FCX 處週期頂部。
B10: 6) 估值結論：12 家中沒有一家達到「安全邊際 ≥15%」的低估門檻（NEE 最接近，+12%）；優質龍頭（LIN/V/BRK/PLD/JPM）都在「合理」區間——這是一個要為質量付合理價的市場。5 年組合加權預期年化 ≈ 9–10%（下表公式連動），高於 S&P 500 盈利收益率 5.2%。
A12: 二、最終 5 年期組合
A13: # | B13: 公司 | C13: Ticker | D13: 建議 | E13: 組合權重 | F13: 股價 | G13: 加權內在價值 | H13: 5Y 預期年化 | I13: 一句話理由
A14: 1 | B14: Linde | C14: LIN | D14: =Picks!Q15 -> 核心持有（首選） | E14: =Picks!R15 -> 0.225 | F14: =Picks!D15 -> 483.73 | G14: =Valuation!V25 -> 454.39251 | H14: =Picks!N15 -> 0.10780256 | I14: 質量+估值兼得，P/E 處 5 年最低 9% 區域
A15: 2 | B15: Berkshire Hathaway | C15: BRK.B | D15: =Picks!Q6 -> 核心持有 | E15: =Picks!R6 -> 0.225 | F15: =Picks!D6 -> 515.62 | G15: =Valuation!V16 -> 524.6895 | H15: =Picks!N6 -> 0.075615552 | I15: 壓艙石：$3,655 億現金 + 回購重啟 + 加息受惠
A16: 3 | B16: Visa | C16: V | D16: =Picks!Q8 -> 核心持有 | E16: =Picks!R8 -> 0.2 | F16: =Picks!D8 -> 385.45 | G16: =Valuation!V18 -> 380.95719 | H16: =Picks!N8 -> 0.10334952 | I16: 最寬護城河之一，價格合理
A17: 4 | B17: Prologis | C17: PLD | D17: =Picks!Q13 -> 核心持有 | E17: =Picks!R13 -> 0.15 | F17: =Picks!D13 -> 129.49 | G17: =Valuation!V23 -> 123.73324 | H17: =Picks!N13 -> 0.10583606 | I17: 低估房地產中質量/價格最平衡，股息 3.3%
A18: 5 | B18: JPMorgan Chase | C18: JPM | D18: =Picks!Q7 -> 核心持有（逢低加碼） | E18: =Picks!R7 -> 0.125 | F18: =Picks!D7 -> 332.99 | G18: =Valuation!V17 -> 317.2187 | H18: =Picks!N7 -> 0.078674857 | I18: 最佳銀行，加息受惠；<$300 加碼
A19: 6 | B19: NextEra Energy | C19: NEE | D19: =Picks!Q9 -> 逆向觀察（小倉位） | E19: =Picks!R9 -> 0.075 | F19: =Picks!D9 -> 77.38 | G19: =Valuation!V19 -> 86.785627 | H19: =Picks!N9 -> 0.11687106 | I19: 逆向：5 年估值低位，等待 Q3 與 Dominion 審批
B20: 組合合計 / 加權預期年化 | E20: =SUM(E14:E19) -> 1 | H20: =Picks!N20 -> 0.096414074
A22: 三、刻意不選的龍頭與原因
B23: WELL / EQIX | C23: 好公司、壞價格：P/B 均處 5 年高位（僅比 8–9% 時間便宜），估值壓縮會吃掉增長。
B24: NEM / FCX | C24: 價格接受者、盈利處金/銅價高位；低 P/E 是週期頂部訊號，不符合巴菲特準則。
B25: CEG / SO | C25: CEG 盈利可預測性不足；SO 高負債、共識多為 Hold，作公用事業備選。
B26: 能源板塊 | C26: Fwd P/E 13.5x 看似最低，但高於 10Y 均值 23%，CY27 EPS −9.3%，油價含地緣溢價。
A28: 四、未來 3 個月關鍵催化劑
B29: • 10/14 美國 9 月 CPI（預期 3.7%）→ 決定 Fed 是否再加息，直接影響 NEE/SO/PLD/WELL
B30: • 10 月中 JPM Q3 業績（NII 指引）、10/21 NEE Q3 業績（Dominion 進展）、10 月底 V 財年業績
B31: • 11–12 月 FOMC：點陣圖指向年底 4.00–4.25%；油價與伊朗局勢
B33: 免責聲明：僅供研究參考，不構成投資建議。

Sheet Sector_Map
A1: 板塊估值地圖 — S&P 500 11 大板塊
A2: 來源：FactSet Earnings Insight 2026-10-09（p.29/30/34/37）；10Y 殖利率連結 Macro!C8。藍字為原始數據，黑字為公式。
A4: 板塊 | B4: ETF | C4: Fwd P/E | D4: 5Y 均值 | E4: 10Y 均值 | F4: vs 10Y | G4: vs 5Y | H4: CY26 EPS 增速 | I4: CY27 EPS 增速 | J4: CY27 營收增速 | K4: PEG (CY27) | L4: 盈利收益率 | M4: EY − 10Y | N4: 目標價上行 | O4: Buy 評級% | P4: 規則判定 (vs10Y ±5%) | Q4: 分析師修正判定 | R4: 關鍵理由 / 估值走向 | S4: 深挖?
A5: 可選消費 Cons. Disc. | B5: XLY | C5: 23.2 | D5: 26 | E5: 25.5 | F5: =C5/E5-1 -> -0.090196078 | G5: =C5/D5-1 -> -0.10769231 | H5: 0.352 | I5: -0.025 | J5: 0.084 | K5: =IF(I5>0,C5/(I5*100),"n/m") -> n/m | L5: =1/C5 -> 0.043103448 | M5: =L5-Macro!$C$8 -> -0.0028965517 | N5: 0.24 | O5: 0.58 | P5: =IF(F5<=-0.05,"低估",IF(F5>=0.05,"高估","合理")) -> 低估 | Q5: 合理偏貴 | R5: 歷史均值被 AMZN/TSLA 高倍數抬高；CY27 EPS −2.5%，估值下修中→「低於均值」不等於便宜 | S5: 否
A6: 工業 Industrials | B6: XLI | C6: 22.8 | D6: 20.9 | E6: 20 | F6: =C6/E6-1 -> 0.14 | G6: =C6/D6-1 -> 0.090909091 | H6: 0.121 | I6: 0.163 | J6: 0.083 | K6: =IF(I6>0,C6/(I6*100),"n/m") -> 1.398773 | L6: =1/C6 -> 0.043859649 | M6: =L6-Macro!$C$8 -> -0.0021403509 | N6: 0.247 | O6: 0.58 | P6: =IF(F6<=-0.05,"低估",IF(F6>=0.05,"高估","合理")) -> 高估 | Q6: 高估 | R6: 國防/電網設備/AI 資本開支題材溢價，較 10Y 均值 +14%；趨勢：溢價擴張 | S6: 否
A7: 必需消費 Staples | B7: XLP | C7: 21.6 | D7: 20.8 | E7: 20.1 | F7: =C7/E7-1 -> 0.074626866 | G7: =C7/D7-1 -> 0.038461538 | H7: 0.075 | I7: 0.069 | J7: 0.042 | K7: =IF(I7>0,C7/(I7*100),"n/m") -> 3.1304348 | L7: =1/C7 -> 0.046296296 | M7: =L7-Macro!$C$8 -> 0.0002962963 | N7: 0.119 | O7: 0.47 | P7: =IF(F7<=-0.05,"低估",IF(F7>=0.05,"高估","合理")) -> 高估 | Q7: 高估 | R7: CY27 EPS 僅 +6.9% 卻 21.6x，PEG 最差；盈利遭下修（WMT/TSN） | S7: 否
A8: 資訊科技 Info. Tech. | B8: XLK | C8: 21.3 | D8: 25.6 | E8: 23.1 | F8: =C8/E8-1 -> -0.077922078 | G8: =C8/D8-1 -> -0.16796875 | H8: 0.534 | I8: 0.416 | J8: 0.292 | K8: =IF(I8>0,C8/(I8*100),"n/m") -> 0.51201923 | L8: =1/C8 -> 0.046948357 | M8: =L8-Macro!$C$8 -> 0.00094835681 | N8: 0.214 | O8: 0.69 | P8: =IF(F8<=-0.05,"低估",IF(F8>=0.05,"高估","合理")) -> 低估 | Q8: 合理（週期頂部風險） | R8: 低 P/E 源於半導體盈利 +130%；PEG 僅 0.5，但若 AI 資本開支放緩 EPS 下修風險大 | S8: 否
A9: S&P 500 | B9: SPY | C9: 19.1 | D9: 19.8 | E9: 19.1 | F9: =C9/E9-1 -> 0 | G9: =C9/D9-1 -> -0.035353535 | H9: 0.327 | I9: 0.158 | J9: 0.094 | K9: =IF(I9>0,C9/(I9*100),"n/m") -> 1.2088608 | L9: =1/C9 -> 0.052356021 | M9: =L9-Macro!$C$8 -> 0.0063560209 | N9: 0.196 | O9: 0.6 | P9: =IF(F9<=-0.05,"低估",IF(F9>=0.05,"高估","合理")) -> 合理 | Q9: 合理 | R9: Fwd 19.1x = 10Y 均值；Trailing 26.0x 偏高；盈利動能強（Q3 +29.6%） | S9: —
A10: 通訊服務 Comm. Svcs | B10: XLC | C10: 18.6 | D10: 18.3 | E10: 17.6 | F10: =C10/E10-1 -> 0.056818182 | G10: =C10/D10-1 -> 0.016393443 | H10: 0.582 | I10: -0.112 | J10: 0.146 | K10: =IF(I10>0,C10/(I10*100),"n/m") -> n/m | L10: =1/C10 -> 0.053763441 | M10: =L10-Macro!$C$8 -> 0.0077634409 | N10: 0.205 | O10: 0.72 | P10: =IF(F10<=-0.05,"低估",IF(F10>=0.05,"高估","合理")) -> 高估 | Q10: 合理偏貴 | R10: CY27 EPS −11.2%（Meta 高基數），表面 P/E 低估盈利回落 | S10: 否
A11: 醫療保健 Health Care | B11: XLV | C11: 18.3 | D11: 17.4 | E11: 16.6 | F11: =C11/E11-1 -> 0.10240964 | G11: =C11/D11-1 -> 0.051724138 | H11: 0.019 | I11: 0.225 | J11: 0.043 | K11: =IF(I11>0,C11/(I11*100),"n/m") -> 0.81333333 | L11: =1/C11 -> 0.054644809 | M11: =L11-Macro!$C$8 -> 0.0086448087 | N11: 0.139 | O11: 0.61 | P11: =IF(F11<=-0.05,"低估",IF(F11>=0.05,"高估","合理")) -> 高估 | Q11: 結構分化 | R11: LLY(41x) 拉高板塊；UNH/MRK/PFE 等權看偏便宜；CY27 EPS 反彈 +22.5% | S11: 觀察
A12: 房地產 Real Estate | B12: XLRE | C12: 16.7 | D12: 18.1 | E12: 18.6 | F12: =C12/E12-1 -> -0.10215054 | G12: =C12/D12-1 -> -0.077348066 | H12: 0.101 | I12: 0.064 | J12: 0.079 | K12: =IF(I12>0,C12/(I12*100),"n/m") -> 2.609375 | L12: =1/C12 -> 0.05988024 | M12: =L12-Macro!$C$8 -> 0.01388024 | N12: 0.235 | O12: 0.55 | P12: =IF(F12<=-0.05,"低估",IF(F12>=0.05,"高估","合理")) -> 低估 | Q12: 低估（需用 P/FFO 驗證） | R12: 加息壓制（Fed 9 月加至 3.75–4.00%）；P/E 對 REIT 失真，PLD 合理、WELL 偏貴 | S12: 是
A13: 原材料 Materials | B13: XLB | C13: 16.6 | D13: 17.9 | E13: 17.8 | F13: =C13/E13-1 -> -0.06741573 | G13: =C13/D13-1 -> -0.072625698 | H13: 0.38 | I13: 0.121 | J13: 0.06 | K13: =IF(I13>0,C13/(I13*100),"n/m") -> 1.3719008 | L13: =1/C13 -> 0.060240964 | M13: =L13-Macro!$C$8 -> 0.014240964 | N13: 0.222 | O13: 0.63 | P13: =IF(F13<=-0.05,"低估",IF(F13>=0.05,"高估","合理")) -> 低估 | Q13: 低估（週期） | R13: 金/銅價高位推升盈利；Q3 盈利預期 −9.6% 下修；龍頭 LIN 處 5 年估值低位 | S13: 是
A14: 公用事業 Utilities | B14: XLU | C14: 16.1 | D14: 18 | E14: 18 | F14: =C14/E14-1 -> -0.10555556 | G14: =C14/D14-1 -> -0.10555556 | H14: 0.13 | I14: 0.089 | J14: 0.049 | K14: =IF(I14>0,C14/(I14*100),"n/m") -> 1.8089888 | L14: =1/C14 -> 0.062111801 | M14: =L14-Macro!$C$8 -> 0.016111801 | N14: 0.211 | O14: 0.53 | P14: =IF(F14<=-0.05,"低估",IF(F14>=0.05,"高估","合理")) -> 低估 | Q14: 低估 | R14: 利率上行令股息吸引力下降（NEE 半年 −17%）；AI 數據中心用電需求是長期支撐 | S14: 是
A15: 金融 Financials | B15: XLF | C15: 14.3 | D15: 14.6 | E15: 13.9 | F15: =C15/E15-1 -> 0.028776978 | G15: =C15/D15-1 -> -0.020547945 | H15: 0.147 | I15: 0.089 | J15: 0.053 | K15: =IF(I15>0,C15/(I15*100),"n/m") -> 1.6067416 | L15: =1/C15 -> 0.06993007 | M15: =L15-Macro!$C$8 -> 0.02393007 | N15: 0.158 | O15: 0.55 | P15: =IF(F15<=-0.05,"低估",IF(F15>=0.05,"高估","合理")) -> 合理 | Q15: 合理（絕對值低） | R15: 絕對 P/E 第二低；銀行應看 P/B-ROE；加息利好 NII，信貸週期是風險 | S15: 是
A16: 能源 Energy | B16: XLE | C16: 13.5 | D16: 12.6 | E16: 11 | F16: =C16/E16-1 -> 0.22727273 | G16: =C16/D16-1 -> 0.071428571 | H16: 0.966 | I16: -0.093 | J16: -0.052 | K16: =IF(I16>0,C16/(I16*100),"n/m") -> n/m | L16: =1/C16 -> 0.074074074 | M16: =L16-Macro!$C$8 -> 0.028074074 | N16: 0.088 | O16: 0.64 | P16: =IF(F16<=-0.05,"低估",IF(F16>=0.05,"高估","合理")) -> 高估 | Q16: 高估（盈利頂部） | R16: 低 P/E 是週期陷阱：油價 $90（伊朗衝突溢價）推高盈利，CY27 EPS −9.3%，較 10Y 均值 +23% | S16: 否
A18: 板塊排序（按 vs 10Y 折讓，公式自動）
A19: 排名 | B19: 板塊 | C19: vs 10Y | D19: Fwd P/E | E19: PEG
A20: 1 | B20: =INDEX($A$5:$A$16,MATCH(SMALL($F$5:$F$16,A20),$F$5:$F$16,0)) -> 公用事業 Utilities | C20: =SMALL($F$5:$F$16,A20) -> -0.10555556 | D20: =INDEX($C$5:$C$16,MATCH(C20,$F$5:$F$16,0)) -> 16.1 | E20: =INDEX($K$5:$K$16,MATCH(C20,$F$5:$F$16,0)) -> 1.8089888
A21: 2 | B21: =INDEX($A$5:$A$16,MATCH(SMALL($F$5:$F$16,A21),$F$5:$F$16,0)) -> 房地產 Real Estate | C21: =SMALL($F$5:$F$16,A21) -> -0.10215054 | D21: =INDEX($C$5:$C$16,MATCH(C21,$F$5:$F$16,0)) -> 16.7 | E21: =INDEX($K$5:$K$16,MATCH(C21,$F$5:$F$16,0)) -> 2.609375
A22: 3 | B22: =INDEX($A$5:$A$16,MATCH(SMALL($F$5:$F$16,A22),$F$5:$F$16,0)) -> 可選消費 Cons. Disc. | C22: =SMALL($F$5:$F$16,A22) -> -0.090196078 | D22: =INDEX($C$5:$C$16,MATCH(C22,$F$5:$F$16,0)) -> 23.2 | E22: =INDEX($K$5:$K$16,MATCH(C22,$F$5:$F$16,0)) -> n/m
A23: 4 | B23: =INDEX($A$5:$A$16,MATCH(SMALL($F$5:$F$16,A23),$F$5:$F$16,0)) -> 資訊科技 Info. Tech. | C23: =SMALL($F$5:$F$16,A23) -> -0.077922078 | D23: =INDEX($C$5:$C$16,MATCH(C23,$F$5:$F$16,0)) -> 21.3 | E23: =INDEX($K$5:$K$16,MATCH(C23,$F$5:$F$16,0)) -> 0.51201923
A24: 5 | B24: =INDEX($A$5:$A$16,MATCH(SMALL($F$5:$F$16,A24),$F$5:$F$16,0)) -> 原材料 Materials | C24: =SMALL($F$5:$F$16,A24) -> -0.06741573 | D24: =INDEX($C$5:$C$16,MATCH(C24,$F$5:$F$16,0)) -> 16.6 | E24: =INDEX($K$5:$K$16,MATCH(C24,$F$5:$F$16,0)) -> 1.3719008
A25: 6 | B25: =INDEX($A$5:$A$16,MATCH(SMALL($F$5:$F$16,A25),$F$5:$F$16,0)) -> S&P 500 | C25: =SMALL($F$5:$F$16,A25) -> 0 | D25: =INDEX($C$5:$C$16,MATCH(C25,$F$5:$F$16,0)) -> 19.1 | E25: =INDEX($K$5:$K$16,MATCH(C25,$F$5:$F$16,0)) -> 1.2088608
A26: 7 | B26: =INDEX($A$5:$A$16,MATCH(SMALL($F$5:$F$16,A26),$F$5:$F$16,0)) -> 金融 Financials | C26: =SMALL($F$5:$F$16,A26) -> 0.028776978 | D26: =INDEX($C$5:$C$16,MATCH(C26,$F$5:$F$16,0)) -> 14.3 | E26: =INDEX($K$5:$K$16,MATCH(C26,$F$5:$F$16,0)) -> 1.6067416
A27: 8 | B27: =INDEX($A$5:$A$16,MATCH(SMALL($F$5:$F$16,A27),$F$5:$F$16,0)) -> 通訊服務 Comm. Svcs | C27: =SMALL($F$5:$F$16,A27) -> 0.056818182 | D27: =INDEX($C$5:$C$16,MATCH(C27,$F$5:$F$16,0)) -> 18.6 | E27: =INDEX($K$5:$K$16,MATCH(C27,$F$5:$F$16,0)) -> n/m
A28: 9 | B28: =INDEX($A$5:$A$16,MATCH(SMALL($F$5:$F$16,A28),$F$5:$F$16,0)) -> 必需消費 Staples | C28: =SMALL($F$5:$F$16,A28) -> 0.074626866 | D28: =INDEX($C$5:$C$16,MATCH(C28,$F$5:$F$16,0)) -> 21.6 | E28: =INDEX($K$5:$K$16,MATCH(C28,$F$5:$F$16,0)) -> 3.1304348
A29: 10 | B29: =INDEX($A$5:$A$16,MATCH(SMALL($F$5:$F$16,A29),$F$5:$F$16,0)) -> 醫療保健 Health Care | C29: =SMALL($F$5:$F$16,A29) -> 0.10240964 | D29: =INDEX($C$5:$C$16,MATCH(C29,$F$5:$F$16,0)) -> 18.3 | E29: =INDEX($K$5:$K$16,MATCH(C29,$F$5:$F$16,0)) -> 0.81333333
A30: 11 | B30: =INDEX($A$5:$A$16,MATCH(SMALL($F$5:$F$16,A30),$F$5:$F$16,0)) -> 工業 Industrials | C30: =SMALL($F$5:$F$16,A30) -> 0.14 | D30: =INDEX($C$5:$C$16,MATCH(C30,$F$5:$F$16,0)) -> 22.8 | E30: =INDEX($K$5:$K$16,MATCH(C30,$F$5:$F$16,0)) -> 1.398773
A31: 12 | B31: =INDEX($A$5:$A$16,MATCH(SMALL($F$5:$F$16,A31),$F$5:$F$16,0)) -> 能源 Energy | C31: =SMALL($F$5:$F$16,A31) -> 0.22727273 | D31: =INDEX($C$5:$C$16,MATCH(C31,$F$5:$F$16,0)) -> 13.5 | E31: =INDEX($K$5:$K$16,MATCH(C31,$F$5:$F$16,0)) -> n/m
A33: 選擇深挖板塊的邏輯
A34: 1) 以「Fwd P/E 相對 10Y 均值」作首輪篩選：公用事業(−10.6%)、房地產(−10.2%)、可選消費(−9.0%)、資訊科技(−7.8%)、原材料(−6.7%) 為表面低估。
A35: 2) 剔除「假便宜」：可選消費與資訊科技的折讓來自盈利暴增/集中度，不是價格便宜（盈利頂部風險）；能源絕對 P/E 最低卻高於歷史 23%，是典型週期陷阱。
A36: 3) 加入金融：絕對 P/E 14.3x 為第二低、略高於 10Y 均值（+2.9%），但 P/B-ROE 框架下龍頭仍合理，且加息環境利好淨息差，屬「低估值板塊」。
A37: 4) 最終深挖：金融、公用事業、房地產、原材料 4 板塊 × 市值前 3 = 12 家龍頭（市值取自 LongBridge 2026-10-09）。

Sheet Methodology
A1: 估值方法論 & 板塊估值算法合理性評估
A2: 各板塊應使用的估值錨，以及「單看 P/E」在何處失真。P/E 適用度：5=很適用，1=基本不適用（分析師判斷）。
A4: 板塊/子行業 | B4: 主估值錨 | C4: 輔助方法 | D4: 為什麼（經濟邏輯） | E4: 單看 P/E 的失真點 | F4: P/E 適用度
A5: 銀行 (JPM) | B5: P/B vs ROE：合理 P/B=(ROE−g)/(r−g)；P/TBV | C5: P/E、股息+回購收益率、CET1 超額資本 | D5: 銀行價值來自權益資本的超額回報；資本受監管約束 | E5: 撥備計提/釋放令 EPS 週期性大起大落；2022 年 P/E 失真 | F5: 3
A6: 保險/綜合控股 (BRK) | B6: P/B、內在價值(營運盈利×倍數+超額現金) | C6: 浮存金成本、分部加總(SOTP) | D6: 巴菲特本人以 P/B 及回購門檻衡量；GAAP 淨利含未實現投資損益 | E6: GAAP EPS 2022 年 −$10.3、2023 年 $44.3，P/E 毫無意義 | F6: 1
A7: 支付網絡 (V/MA) | B7: P/E、FCF 收益率、PEG | C7: DCF（高轉換率 FCF≈淨利） | D7: 輕資產、FCF 轉換率 >100%、增長可預測 | E7: 訴訟撥備(每季 $0.6–1.0B) 壓低 GAAP EPS；需用調整後 | F7: 5
A8: 受監管公用事業 (NEE/SO) | B8: Fwd P/E vs 10Y 殖利率；股息折現(DDM) | C8: 費率基礎(rate base)增長 × 允許 ROE | D8: 盈利=允許回報×費率基礎；類債券資產，對利率敏感 | E8: 一次性項目(NEE GAAP vs 調整後差異大)；忽略負 FCF 與股權攤薄 | F8: 4
A9: 獨立發電 (CEG) | B9: EV/EBITDA、FCF 收益率 | C9: P/E、合約(PPA)覆蓋率 | D9: 收入隨電價/產能拍賣波動；數據中心 PPA 決定估值上限 | E9: 公允價值調整與 Calpine 併購攤銷令 GAAP 失真 | F9: 3
A10: REITs (WELL/PLD/EQIX) | B10: P/FFO、P/AFFO、NAV/隱含資本化率 | C10: 股息收益率 vs 10Y、DCF | D10: 房地產折舊非真實經濟成本；REIT 須派 90% 應稅收入 | E10: WELL GAAP P/E 105x vs P/FFO 35x；EQIX 66x vs P/AFFO 24x — P/E 完全失真 | F10: 1
A11: 工業氣體 (LIN) | B11: P/E、EV/EBITDA | C11: ROC、合約 backlog | D11: 15–20 年照付不議合約，盈利穩定如公用事業但增長更快 | E11: 較少失真；需看調整後 EPS（剔除俄羅斯減值等） | F11: 5
A12: 金屬礦業 (NEM/FCX) | B12: P/NAV、中週期價格下 EV/EBITDA | C12: 在期貨曲線下的 FCF 收益率、AISC 曲線位置 | D12: 價格接受者，價值=儲量×(價格−成本) | E12: 金價 $4,500 / 銅價 $6.5 時 P/E 最低 → 週期頂部陷阱 | F12: 2
A13: 能源 (XOM/CVX) | B13: 中週期油價($65–70)下 EV/EBITDA、FCF 收益率 | C13: P/CF、儲量替代率 | D13: 盈利與油價高度相關 | E13: 油價 $90 時 Fwd P/E 13.5x 看似便宜，CY27 EPS −9.3% | F13: 2
A14: 資訊科技 | B14: 成熟：P/E；高增長：EV/Sales、PEG | C14: Rule of 40、DCF | D14: 增長率差異極大；半導體有強週期 | E14: 半導體盈利 +130% 令板塊 P/E 低於均值，週期頂部風險 | F14: 3
A15: 醫療保健 | B15: P/E + 管線 rNPV | C15: 專利懸崖調整後 EPS | D15: 專利到期導致盈利斷崖 | E15: LLY 一家拉高板塊；收購研發費用一次性扣除(MRK P/E 113x) | F15: 3
A16: 必需消費 | B16: P/E、股息率 vs 債券 | C16: EV/EBITDA | D16: 低增長、類債券 | E16: 低增長配高倍數時 P/E 看似「合理」但 PEG 很差 | F16: 4
A18: 板塊估值算法（FactSet 加總 Fwd P/E）合理性評估
A19: 偏差來源 | B19: 說明 | C19: 影響 | D19: 本分析的修正方式
A20: 市值加權偏差 | B20: 板塊 P/E = 板塊總市值 ÷ 總預期盈利，被巨頭主導（IT 前 3 大佔比過半；醫療被 LLY 主導）。 | C20: 高 | D20: 同時看等權 P/E 與中位數（本表 Comps 用個股中位數交叉驗證）
A21: 一致預期樂觀偏差 | B21: 歷史上分析師季內平均下修 EPS 2–4%；本季反而上修 1.4%，盈利動能強但頂部特徵明顯。 | C21: 中 | D21: 對週期股用中週期/正常化盈利
A22: 週期頂部陷阱 | B22: 能源/原材料/半導體在盈利高峰時 P/E 最低，按 P/E 會買在頂部。 | C22: 高 | D22: 用 EV/EBITDA@中週期價格、P/NAV
A23: 利率環境未調整 | B23: 10Y 均值含 2020–21 零利率時期；現 10Y ≈4.6%、Fed 加息至 3.75–4.00%，合理倍數中樞應低於歷史均值。 | C23: 高 | D23: 看盈利收益率−10Y 的股權風險溢價（Sector_Map M 欄）
A24: GICS 分類變更 | B24: 2018 年 GOOGL/META 移入通訊；2023 年 V/MA 移入金融 → 金融板塊 P/E 歷史不可比（結構性上移）。 | C24: 中 | D24: 金融板塊 P/E 略高於 10Y 均值部分源於此，不代表變貴
A25: 會計口徑 | B25: REIT 折舊、保險未實現損益、併購攤銷令 GAAP P/E 失真。 | C25: 高 | D25: 各行業採用專屬指標（見上表）
A26: 結論 | B26: FactSet 板塊 Fwd P/E 適合作「首輪篩選」，不足以作買入依據；本工作簿以個股層面多方法估值 + 歷史分位 + 反向 DCF 交叉驗證。 | C26: — | D26: —

Sheet Competition
A1: 板塊內部競爭方式 & 護城河來源
A2: 分析師判斷 + 公司公開資料；市值為 LongBridge 2026-10-09。
A4: 板塊/子行業 | B4: 競爭方式（靠什麼贏） | C4: 集中度/格局 | D4: 市值前 3（$B） | E4: 護城河來源 & 龍頭優勢
A5: 金融—銀行 | B5: 存款成本(低成本存款基礎)、規模攤薄科技投入(JPM 年科技支出~$18B)、監管資本作門檻、交叉銷售 | C5: 寡頭化：前 4 大銀行佔美國存款約 4 成；大而不倒隱性擔保 | D5: BRK 1,112 / JPM 885 / V 742 | E5: JPM：全業務線前 3、資產負債表堡壘、ROE 16–18%；V：雙邊網絡效應(持卡人×商戶)，與 MA 形成雙寡頭；BRK：低成本浮存金 + 永久資本 + 收購對象首選買家
A6: 金融—支付 | B6: 網絡效應、受理覆蓋、品牌信任、安全/風控；新威脅：穩定幣、A2A 即時支付、CCCA 法案 | C6: V/MA 雙寡頭（Amex/Discover 次之） | D6: V 742 / MA 516 | E6: 邊際成本近零、毛利 97.8%、ROE >50%
A7: 公用事業—受監管 | B7: 不爭客戶，爭「費率基礎增長 + 監管關係 + 資本成本」；大型負荷(數據中心)合約成新戰場 | C7: 地區性壟斷 | D7: NEE 161 / CEG 106 / SO 99 | E7: NEE：FPL 最優營運效率 + 全美最大再生能源開發商；SO：東南部 17GW 大型負荷合約（含 OpenAI 3.2GW）；CEG：全美最大核電機組群(稀缺零碳基載)
A8: 公用事業—獨立發電 | B8: 發電成本曲線位置、核電/燃氣稀缺性、與超大規模雲廠商的長期 PPA | C8: 分散，但核電高度集中於 CEG/VST | D8: CEG 106 / VST 54 | E8: 核電執照與既有站點不可複製
A9: 房地產—REITs | B9: 地段 + 規模 + 資本成本 + 營運平台；數據中心看電力與互聯生態 | C9: 子行業內寡頭（物流 PLD、數據中心 EQIX/DLR、醫療 WELL/VTR） | D9: WELL 163 / PLD 121 / EQIX 101 | E9: PLD：全球物流 ~12 億平方呎、客戶網絡、數據中心電力管線 5.8GW；EQIX：互聯網絡效應(客戶間直連)；WELL：長者住宅數據化營運平台、SHO 同店 NOI +20.5%
A10: 原材料—工業氣體 | B10: 現場製氣長約(15–20 年照付不議)、管道網絡區域密度、轉換成本高 | C10: 三寡頭：Linde / Air Liquide / Air Products | D10: LIN 223 | E10: LIN：區域密度 + 合約 backlog $11B + 電子特氣；定價權可傳導通脹
A11: 原材料—金屬礦業 | B11: 成本曲線位置(AISC 分位)、儲量壽命、司法管轄區風險；無定價權 | C11: 分散；價格接受者 | D11: NEM 124 / FCX 106 | E11: NEM：全球最大金礦商、AISC $1,621/oz；FCX：Grasberg/美洲一級銅礦，但 2025 泥石流事故後產能 65%→2027 年底恢復
A12: 對照—能源 | B12: 上游成本、儲量、資本紀律；下游煉油價差 | C12: XOM/CVX 寡頭 | D12: XOM 695 / CVX 419 | E12: 週期性強；本輪不深挖（盈利頂部）

Sheet Macro
A1: 宏觀儀表板 & 個股宏觀敏感度
A2: 來源：LongBridge macrodata（CPI、失業率）；CNBC/Fed（政策利率）；FactSet（油價、盈利）；Webull/FCX（金價）。黃底=可調關鍵假設。
A4: A. 關鍵宏觀指標
A5: 指標 | B5: 最新期 | C5: 數值 | D5: 前值 | E5: 趨勢 | F5: 來源
A6: CPI 同比 (%) | B6: 2026-08 | C6: 0.034 | D6: 0.034 | E6: 高位橫行（5 月峰值 4.2%） | F6: LongBridge 30771871
A7: 核心 CPI 同比 (%) | B7: 2026-05 | C7: 0.029 | E7: 溫和 | F7: BLS via 媒體
A8: 10Y 美債殖利率 (估) | B8: 2026-09 | C8: 0.046 | E8: 4.6–4.8% 區間（關鍵假設） | F8: Fed H.15 / YCharts (7/24 4.66%, 9/2 4.79%)
A9: 聯邦基金利率上限 | B9: 2026-09-16 | C9: 0.04 | D9: 0.0375 | E9: 加息 25bp（2023 年後首次） | F9: CNBC / FOMC
A10: 失業率 (%) | B10: 2026-09 | C10: 0.042 | D10: 0.041 | E10: 穩定（峰值 4.6%） | F10: LongBridge 30771865
A11: WTI 原油 ($/bbl) | B11: 2026-09-30 | C11: 90.42 | D11: 69.5 | E11: Q3 +30%（伊朗衝突） | F11: FactSet EI
A12: 金價 Q2 均價 ($/oz) | B12: 2026-Q2 | C12: 4520 | D12: 3291 | E12: 高位 | F12: Webull / FCX 8-K
A13: S&P 500 Q3 EPS 增速 | B13: 2026-Q3E | C13: 0.296 | D13: 0.267 | E13: 強勁上修 | F13: FactSet EI
A14: S&P 500 CY27 EPS 增速 | B14: 2027E | C14: 0.158 | E14: 放緩 | F14: FactSet EI
A15: S&P 500 Fwd P/E | B15: 2026-10-09 | C15: 19.1 | D15: 20.4 | E15: 回落至 10Y 均值 | F15: FactSet EI
A17: B. 當前宏觀體制（Regime）— 方向權重（可調）
A18: 因子 | B18: 利率上行 | C18: 通脹/油價上行 | D18: 經濟衰退 | E18: AI 資本開支/用電 | F18: 監管政策風險 | G18: 美元走強
A19: 體制強度 (0–1) | B19: 1 | C19: 0.8 | D19: 0.3 | E19: 1 | F19: 0.5 | G19: 0.2
A20: 依據 | B20: Fed 9 月加息、點陣圖指向再加一次 | C20: CPI 3.4%、油價 $90 | D20: 失業率 4.2% 穩定，概率低 | E20: Q3 IT 盈利 +65%、公用事業大負荷合約 | F20: CCCA、併購審批、關稅 | G20: 方向不明
A22: C. 個股宏觀敏感度（−2 極負面 … +2 極正面；分析師判斷）→ 宏觀得分 = Σ 敏感度 × 體制強度
A23: 公司 | B23: 利率上行 | C23: 通脹/油價上行 | D23: 經濟衰退 | E23: AI 資本開支/用電 | F23: 監管政策風險 | G23: 美元走強 | H23: 宏觀得分 | I23: 韌性分(0–5) | J23: 主要宏觀邏輯
A24: BRK.B | B24: 1 | C24: 0 | D24: -1 | E24: 0 | F24: 0 | G24: 0 | H24: =SUMPRODUCT(B24:G24,$B$19:$G$19) -> 0.7 | I24: =MAX(0,MIN(5,ROUND(2.5+H24,0))) -> 3 | J24: 浮存金與 $3,600 億現金受惠高利率；分散化抗衰退
A25: JPM | B25: 1 | C25: 0 | D25: -2 | E25: 0 | F25: 1 | G25: 0 | H25: =SUMPRODUCT(B25:G25,$B$19:$G$19) -> 0.9 | I25: =MAX(0,MIN(5,ROUND(2.5+H25,0))) -> 3 | J25: 加息擴大 NII（2026 指引 $1,055 億）；衰退時信貸成本上升
A26: V | B26: 0 | C26: 1 | D26: -1 | E26: 0 | F26: -1 | G26: -1 | H26: =SUMPRODUCT(B26:G26,$B$19:$G$19) -> -0.2 | I26: =MAX(0,MIN(5,ROUND(2.5+H26,0))) -> 2 | J26: 名義消費額隨通脹上升；CCCA/DOJ 訴訟；強美元壓跨境
A27: NEE | B27: -2 | C27: -1 | D27: 0 | E27: 2 | F27: -1 | G27: 0 | H27: =SUMPRODUCT(B27:G27,$B$19:$G$19) -> -1.3 | I27: =MAX(0,MIN(5,ROUND(2.5+H27,0))) -> 1 | J27: 重資本、高負債最怕加息；Dominion 併購審批；AI 用電長期利好
A28: CEG | B28: -1 | C28: 1 | D28: -1 | E28: 2 | F28: 0 | G28: 0 | H28: =SUMPRODUCT(B28:G28,$B$19:$G$19) -> 1.5 | I28: =MAX(0,MIN(5,ROUND(2.5+H28,0))) -> 4 | J28: 電價上行與數據中心 PPA 利好；併購 Calpine 增加商品價格暴露
A29: SO | B29: -1 | C29: 0 | D29: 0 | E29: 2 | F29: 0 | G29: 0 | H29: =SUMPRODUCT(B29:G29,$B$19:$G$19) -> 1 | I29: =MAX(0,MIN(5,ROUND(2.5+H29,0))) -> 4 | J29: 17GW 大型負荷合約鎖定增長；受監管回報抵禦衰退
A30: WELL | B30: -1 | C30: 0 | D30: 0 | E30: 0 | F30: 0 | G30: 0 | H30: =SUMPRODUCT(B30:G30,$B$19:$G$19) -> -1 | I30: =MAX(0,MIN(5,ROUND(2.5+H30,0))) -> 2 | J30: 人口老化需求剛性；高估值對利率敏感
A31: PLD | B31: -1 | C31: 1 | D31: -1 | E31: 1 | F31: -1 | G31: 0 | H31: =SUMPRODUCT(B31:G31,$B$19:$G$19) -> 0 | I31: =MAX(0,MIN(5,ROUND(2.5+H31,0))) -> 3 | J31: 租金可隨通脹調升；關稅/貿易量風險；數據中心轉型
A32: EQIX | B32: -1 | C32: 0 | D32: 0 | E32: 2 | F32: 0 | G32: -1 | H32: =SUMPRODUCT(B32:G32,$B$19:$G$19) -> 0.8 | I32: =MAX(0,MIN(5,ROUND(2.5+H32,0))) -> 3 | J32: AI 推理/互聯需求；重資本開支 $50–60 億
A33: LIN | B33: 0 | C33: 1 | D33: -1 | E33: 1 | F33: 0 | G33: -1 | H33: =SUMPRODUCT(B33:G33,$B$19:$G$19) -> 1.3 | I33: =MAX(0,MIN(5,ROUND(2.5+H33,0))) -> 4 | J33: 合約通脹轉嫁；電子特氣受惠半導體擴產；工業產量週期
A34: NEM | B34: -1 | C34: 2 | D34: 1 | E34: 0 | F34: 0 | G34: -2 | H34: =SUMPRODUCT(B34:G34,$B$19:$G$19) -> 0.5 | I34: =MAX(0,MIN(5,ROUND(2.5+H34,0))) -> 3 | J34: 實際利率上行不利金價；避險屬性；強美元利空
A35: FCX | B35: 0 | C35: 1 | D35: -2 | E35: 2 | F35: -1 | G35: -1 | H35: =SUMPRODUCT(B35:G35,$B$19:$G$19) -> 1.5 | I35: =MAX(0,MIN(5,ROUND(2.5+H35,0))) -> 4 | J35: 電網/數據中心拉動銅需求；衰退敏感；印尼政策風險

Sheet Comps
A1: 可比公司估值表 — 4 板塊 × 市值前 3 龍頭
A2: 市場數據：LongBridge calc_indexes / valuation_history / institution_rating（2026-10-09）。Fwd EPS = LongBridge 一致預期中位數（下一財年，≈FY2027E；BRK 為營運 EPS、REIT 為 GAAP EPS）。
A4: Ticker | B4: 公司 | C4: 板塊 | D4: 子行業 | E4: 股價 ($) | F4: 市值 ($B) | G4: 股數 (B) | H4: P/E TTM | I4: Fwd EPS ($) | J4: Fwd P/E | K4: P/B | L4: 股息率 | M4: ROE FY25 | N4: ROE 5Y均 | O4: 營收 5Y CAGR | P4: EPS 5Y CAGR | Q4: 淨利率 FY25 | R4: 負債/資產 | S4: 估值指標 | T4: 當前 | U4: 歷史低 | V4: 歷史中位 | W4: 歷史高 | X4: 比歷史 X% 時間便宜 | Y4: 區間 | Z4: 行業中位 | AA4: YTD | AB4: Buy | AC4: Over | AD4: Hold | AE4: Under+Sell | AF4: 總數
A5: BRK.B | B5: Berkshire Hathaway | C5: 金融 | D5: 多元控股/保險 | E5: 515.62 | F5: 1112.126 | G5: =F5/E5 -> 2.1568713 | H5: 12.97 | I5: 22.163 | J5: =E5/I5 -> 23.264901 | K5: 1.49 | L5: 0 | M5: =Financials!D8 -> 0.098 | N5: =Financials!J8 -> 0.1148 | O5: =Financials!J5 -> 0.0862766 | P5: =Financials!J7 -> 0.11788722 | Q5: =Financials!D6/Financials!D5 -> 0.18029097 | R5: =Financials!G12 -> 0.41112982 | S5: P/B | T5: 1.49 | U5: 1.38 | V5: 1.46 | W5: 1.59 | X5: 0.441 | Y5: 5Y | Z5: 1.48 | AA5: 0.0258 | AB5: 2 | AC5: 0 | AD5: 2 | AE5: 0 | AF5: 4
A6: JPM | B6: JPMorgan Chase | C6: 金融 | D6: 多元化銀行 | E6: 332.99 | F6: 885.149 | G6: =F6/E6 -> 2.6581849 | H6: 13.91 | I6: 24.46 | J6: =E6/I6 -> 13.613655 | K6: 2.5 | L6: 0.0185 | M6: =Financials!D16 -> 0.1669 | N6: =Financials!J16 -> 0.1675 | O6: =Financials!J13 -> 0.10423898 | P6: =Financials!J15 -> 0.17654955 | Q6: =Financials!D14/Financials!D13 -> 0.33097156 | R6: =Financials!G17 -> 0.91809126 | S6: P/E | T6: 13.91 | U6: 11.37 | V6: 13.07 | W6: 14.84 | X6: 0.4043 | Y6: 3Y | Z6: 11.99 | AA6: 0.0533 | AB6: 9 | AC6: 4 | AD6: 12 | AE6: 0 | AF6: 26
A7: V | B7: Visa | C7: 金融 | D7: 支付網絡 | E7: 385.45 | F7: 741.555 | G7: =F7/E7 -> 1.9238682 | H7: 33.11 | I7: 14.493 | J7: =E7/I7 -> 26.595598 | K7: 21.39 | L7: 0.007 | M7: =Financials!D21 -> 0.5275 | N7: =Financials!J21 -> 0.4653 | O7: =Financials!J18 -> 0.12859368 | P7: =Financials!J20 -> 0.15839924 | Q7: =Financials!D19/Financials!D18 -> 0.496325 | R7: =Financials!G25 -> 0.6194907 | S7: P/E | T7: 33.11 | U7: 29.01 | V7: 31.33 | W7: 33.13 | X7: 0.2015 | Y7: 3Y | Z7: 14.11 | AA7: 0.1057 | AB7: 27 | AC7: 9 | AD7: 3 | AE7: 1 | AF7: 41
A8: NEE | B8: NextEra Energy | C8: 公用事業 | D8: 受監管電力+再生能源 | E8: 77.38 | F8: 161.413 | G8: =F8/E8 -> 2.0859783 | H8: 17.36 | I8: 4.155 | J8: =E8/I8 -> 18.623345 | K8: 2.83 | L8: 0.0315 | M8: =Financials!D29 -> 0.1306 | N8: =Financials!J29 -> 0.1294 | O8: =Financials!J26 -> 0.087797663 | P8: =Financials!J28 -> 0.17395228 | Q8: =Financials!D27/Financials!D26 -> 0.24934335 | R8: =Financials!G31 -> 0.68748267 | S8: P/E | T8: 17.36 | U8: 19.15 | V8: 25.22 | W8: 42.59 | X8: 0.8666 | Y8: 5Y | Z8: 18.73 | AA8: -0.0151 | AB8: 11 | AC8: 3 | AD8: 6 | AE8: 1 | AF8: 22
A9: CEG | B9: Constellation Energy | C9: 公用事業 | D9: 獨立發電(核電) | E9: 298.07 | F9: 105.608 | G9: =F9/E9 -> 0.35430604 | H9: 30.48 | I9: 12.041 | J9: =E9/I9 -> 24.754588 | K9: 3.3 | L9: 0.0056 | M9: =Financials!D35 -> 0.1675 | N9: =Financials!J35 -> 0.11896 | O9: =Financials!J32 -> 0.077216585 | P9: =Financials!J34 -> n/m | Q9: =Financials!D33/Financials!D32 -> 0.09082364 | R9: =Financials!G37 -> 0.74055442 | S9: P/E | T9: 30.48 | U9: 23.77 | V9: 28.93 | W9: 37.11 | X9: 0.4707 | Y9: 3Y | Z9: 18.73 | AA9: -0.1525 | AB9: 13 | AC9: 6 | AD9: 3 | AE9: 0 | AF9: 22
A10: SO | B10: Southern Co. | C10: 公用事業 | D10: 受監管電力 | E10: 86.17 | F10: 99.127 | G10: =F10/E10 -> 1.1503656 | H10: 21.28 | I10: 4.633 | J10: =E10/I10 -> 18.59918 | K10: 2.51 | L10: 0.0348 | M10: =Financials!D41 -> 0.1254 | N10: =Financials!J41 -> 0.11934 | O10: =Financials!J38 -> 0.077211029 | P10: =Financials!J40 -> 0.059945876 | Q10: =Financials!D39/Financials!D38 -> 0.14688864 | R10: =Financials!G43 -> 0.75040457 | S10: P/E | T10: 21.28 | U10: 20.52 | V10: 22.49 | W10: 25.05 | X10: 0.6894 | Y10: 5Y | Z10: 18.73 | AA10: 0.0125 | AB10: 6 | AC10: 1 | AD10: 14 | AE10: 2 | AF10: 23
A11: WELL | B11: Welltower | C11: 房地產 | D11: 醫療/長者住宅REIT | E11: 225.47 | F11: 162.506 | G11: =F11/E11 -> 0.72074334 | H11: 104.8 | I11: 2.83 | J11: =E11/I11 -> 79.671378 | K11: 3.5 | L11: 0.0136 | M11: =Financials!D47 -> 0.0253 | N11: =Financials!J47 -> 0.02016 | O11: =Financials!J44 -> 0.18763799 | P11: =Financials!J46 -> -0.098155262 | Q11: =Financials!D45/Financials!D44 -> 0.086455066 | R11: =Financials!G49 -> 0.35808211 | S11: P/B | T11: 3.5 | U11: 1.82 | V11: 2.19 | W11: 3.2 | X11: 0.0782 | Y11: 5Y | Z11: 1.36 | AA11: 0.2278 | AB11: 12 | AC11: 6 | AD11: 4 | AE11: 0 | AF11: 22
A12: PLD | B12: Prologis | C12: 房地產 | D12: 物流REIT | E12: 129.49 | F12: 120.715 | G12: =F12/E12 -> 0.93223415 | H12: 28.72 | I12: 3.48 | J12: =E12/I12 -> 37.20977 | K12: 2.25 | L12: 0.0326 | M12: =Financials!D53 -> 0.0621 | N12: =Financials!J53 -> 0.07134 | O12: =Financials!J50 -> 0.14185015 | P12: =Financials!J52 -> 0.12111661 | Q12: =Financials!D51/Financials!D50 -> 0.36136191 | R12: =Financials!G55 -> 0.41499534 | S12: P/B | T12: 2.25 | U12: 1.94 | V12: 2.11 | W12: 2.45 | X12: 0.3574 | Y12: 5Y | Z12: 1.36 | AA12: 0.0381 | AB12: 7 | AC12: 3 | AD12: 7 | AE12: 0 | AF12: 18
A13: EQIX | B13: Equinix | C13: 房地產 | D13: 數據中心REIT | E13: 1026.06 | F13: 101.243 | G13: =F13/E13 -> 0.098671618 | H13: 66.04 | I13: 17.015 | J13: =E13/I13 -> 60.303262 | K13: 7.04 | L13: 0.0197 | M13: =Financials!D59 -> 0.0975 | N13: =Financials!J59 -> 0.0701 | O13: =Financials!J56 -> 0.10491427 | P13: =Financials!J58 -> 0.26907834 | Q13: =Financials!D57/Financials!D56 -> 0.14578834 | R13: =Financials!G61 -> 0.64679505 | S13: P/B | T13: 7.04 | U13: 5.53 | V13: 5.99 | W13: 6.7 | X13: 0.0867 | Y13: 5Y | Z13: 1.36 | AA13: 0.3597 | AB13: 23 | AC13: 5 | AD13: 6 | AE13: 0 | AF13: 34
A14: LIN | B14: Linde | C14: 原材料 | D14: 工業氣體 | E14: 483.73 | F14: 222.99 | G14: =F14/E14 -> 0.4609803 | H14: 30.78 | I14: 18.74 | J14: =E14/I14 -> 25.8127 | K14: 5.71 | L14: 0.013 | M14: =Financials!D65 -> 0.1807 | N14: =Financials!J65 -> 0.13746 | O14: =Financials!J62 -> 0.045223161 | P14: =Financials!J64 -> 0.25408179 | Q14: =Financials!D63/Financials!D62 -> 0.20296593 | R14: =Financials!G69 -> 0.54224403 | S14: P/E | T14: 30.78 | U14: 32.29 | V14: 33.68 | W14: 39.91 | X14: 0.908 | Y14: 5Y | Z14: 29.45 | AA14: 0.1457 | AB14: 17 | AC14: 5 | AD14: 5 | AE14: 1 | AF14: 28
A15: NEM | B15: Newmont | C15: 原材料 | D15: 黃金開採 | E15: 117.84 | F15: 124.167 | G15: =F15/E15 -> 1.0536914 | H15: 14.44 | I15: 8.99 | J15: =E15/I15 -> 13.107898 | K15: 3.52 | L15: 0.0087 | M15: =Financials!D73 -> 0.2221 | N15: =Financials!J73 -> 0.05126 | O15: =Financials!J70 -> 0.14543267 | P15: =Financials!J72 -> 0.12729803 | Q15: =Financials!D71/Financials!D70 -> 0.31254136 | R15: =Financials!G77 -> 0.40403704 | S15: P/E | T15: 14.44 | U15: 13.1 | V15: 14.92 | W15: 17.3 | X15: 0.5632 | Y15: 1Y | Z15: 8.53 | AA15: 0.1878 | AB15: 15 | AC15: 5 | AD15: 2 | AE15: 1 | AF15: 23
A16: FCX | B16: Freeport-McMoRan | C16: 原材料 | D16: 銅金開採 | E16: 73.69 | F16: 105.82 | G16: =F16/E16 -> 1.4360157 | H16: 36.04 | I16: 3.8 | J16: =E16/I16 -> 19.392105 | K16: 5.26 | L16: 0.0051 | M16: =Financials!D81 -> 0.1204 | N16: =Financials!J81 -> 0.18698 | O16: =Financials!J78 -> 0.12788497 | P16: =Financials!J80 -> 0.29960671 | Q16: =Financials!D79/Financials!D78 -> 0.084777156 | R16: =Financials!G85 -> 0.47107466 | S16: P/E | T16: 36.04 | U16: 29.07 | V16: 32.55 | W16: 37.75 | X16: 0.2679 | Y16: 3Y | Z16: 31.2 | AA16: 0.4612 | AB16: 12 | AC16: 6 | AD16: 4 | AE16: 1 | AF16: 24
B18: 中位數 | H18: =MEDIAN(H5:H16) -> 29.6 | J18: =MEDIAN(J5:J16) -> 24.009745 | K18: =MEDIAN(K5:K16) -> 3.4 | L18: =MEDIAN(L5:L16) -> 0.0133 | M18: =MEDIAN(M5:M16) -> 0.128 | N18: =MEDIAN(N5:N16) -> 0.11915 | O18: =MEDIAN(O5:O16) -> 0.10457662 | Q18: =MEDIAN(Q5:Q16) -> 0.19162845 | X18: =MEDIAN(X5:X16) -> 0.42265
B19: 平均數 | H19: =AVERAGE(H5:H16) -> 34.160833 | J19: =AVERAGE(J5:J16) -> 30.079032 | K19: =AVERAGE(K5:K16) -> 5.1083333 | L19: =AVERAGE(L5:L16) -> 0.015841667 | M19: =AVERAGE(M5:M16) -> 0.16033333 | N19: =AVERAGE(N5:N16) -> 0.13771667 | O19: =AVERAGE(O5:O16) -> 0.10952315 | Q19: =AVERAGE(Q5:Q16) -> 0.22404441 | X19: =AVERAGE(X5:X16) -> 0.444575
A21: 註：
A22: BRK、WELL、PLD、EQIX 的估值區間以 P/B 計（LongBridge 提供）；REIT 的 P/E 因折舊失真，見 Valuation 頁 P/FFO。
A23: 「比歷史 X% 時間便宜」= 當前倍數低於該區間內多少比例的歷史觀測值（越高越便宜）。NEM 僅 1 年區間、JPM/V/CEG/FCX 為 3 年。
A24: CEG FY2021/2020 EPS 缺失，EPS CAGR 顯示 n/m。WELL/PLD/EQIX 的 GAAP ROE 被折舊壓低，不代表經濟回報。

Sheet Financials
A1: 財務數據 FY2025–FY2020（年報）
A2: 來源：LongBridge financial_report（annual）。V 財年截至 9 月。BRK 淨利含未實現投資損益。單位：$B（EPS、ROE 除外）。FCF = OCF − CapEx（有 CapEx 數據者）。
A4: Ticker | B4: 指標 | C4: 單位 | D4: FY2025 | E4: FY2024 | F4: FY2023 | G4: FY2022 | H4: FY2021 | I4: FY2020 | J4: 5Y CAGR/均值
A5: BRK.B | B5: 營業收入 Revenue | C5: $B | D5: 371.444 | E5: 371.433 | F5: 364.482 | G5: 302.02 | H5: 276.185 | I5: 245.579 | J5: =IFERROR((D5/I5)^(1/5)-1,"n/m") -> 0.0862766
A6: BRK.B | B6: 淨利潤 Net income | C6: $B | D6: 66.968 | E6: 88.995 | F6: 96.223 | G6: -22.759 | H6: 89.937 | I6: 42.521
A7: BRK.B | B7: 每股收益 EPS | C7: $ | D7: 31.04 | E7: 41.27 | F7: 44.27 | G7: -10.33 | H7: 39.7 | I7: 17.78 | J7: =IFERROR((D7/I7)^(1/5)-1,"n/m") -> 0.11788722
A8: BRK.B | B8: ROE | C8: % | D8: 0.098 | E8: 0.147 | F8: 0.186 | G8: -0.0465 | H8: 0.1895 | I8: 0.098 | J8: =AVERAGE(D8:H8) -> 0.1148
A9: BRK.B | B9: 經營現金流 OCF | C9: $B | D9: 45.969 | E9: 30.592 | F9: 49.196 | G9: 37.35 | H9: 39.427 | I9: 39.773
A10: BRK.B | B10: 資本開支 CapEx | C10: $B | D10: 20.927 | E10: 18.976 | F10: 19.409 | G10: 15.464 | H10: 13.276 | I10: 13.012
A11: BRK.B | B11: 自由現金流 FCF | C11: $B | D11: =D9-D10 -> 25.042 | E11: =E9-E10 -> 11.616 | F11: =F9-F10 -> 29.787 | G11: =G9-G10 -> 21.886 | H11: =H9-H10 -> 26.151 | I11: =I9-I10 -> 26.761
A12: BRK.B | B12: 總資產 / 總負債 FY25 | C12: $B | D12: 1222.176 | E12: 502.473 | F12: 負債/資產 | G12: =E12/D12 -> 0.41112982
A13: JPM | B13: 營業收入 Revenue | C13: $B | D13: 168.235 | E13: 166.775 | F13: 145.67 | G13: 122.306 | H13: 130.898 | I13: 102.471 | J13: =IFERROR((D13/I13)^(1/5)-1,"n/m") -> 0.10423898
A14: JPM | B14: 淨利潤 Net income | C14: $B | D14: 55.681 | E14: 56.868 | F14: 47.76 | G14: 35.892 | H14: 46.503 | I14: 27.41
A15: JPM | B15: 每股收益 EPS | C15: $ | D15: 20.02 | E15: 19.75 | F15: 16.23 | G15: 12.09 | H15: 15.36 | I15: 8.88 | J15: =IFERROR((D15/I15)^(1/5)-1,"n/m") -> 0.17654955
A16: JPM | B16: ROE | C16: % | D16: 0.1669 | E16: 0.1819 | F16: 0.1689 | G16: 0.1369 | H16: 0.1829 | I16: 0.1134 | J16: =AVERAGE(D16:H16) -> 0.1675
A17: JPM | B17: 總資產 / 總負債 FY25 | C17: $B | D17: 4424.9 | E17: 4062.462 | F17: 負債/資產 | G17: =E17/D17 -> 0.91809126
A18: V | B18: 營業收入 Revenue | C18: $B | D18: 40 | E18: 35.926 | F18: 32.653 | G18: 29.31 | H18: 24.105 | I18: 21.846 | J18: =IFERROR((D18/I18)^(1/5)-1,"n/m") -> 0.12859368
A19: V | B19: 淨利潤 Net income | C19: $B | D19: 19.853 | E19: 19.457 | F19: 16.989 | G19: 14.63 | H19: 12.008 | I19: 10.475
A20: V | B20: 每股收益 EPS | C20: $ | D20: 10.2 | E20: 9.73 | F20: 8.28 | G20: 7 | H20: 5.63 | I20: 4.89 | J20: =IFERROR((D20/I20)^(1/5)-1,"n/m") -> 0.15839924
A21: V | B21: ROE | C21: % | D21: 0.5275 | E21: 0.5179 | F21: 0.4834 | G21: 0.4318 | H21: 0.3659 | I21: 0.3472 | J21: =AVERAGE(D21:H21) -> 0.4653
A22: V | B22: 經營現金流 OCF | C22: $B | D22: 23.059 | E22: 19.95 | F22: 20.755 | G22: 18.849 | H22: 15.227 | I22: 10.44
A23: V | B23: 資本開支 CapEx | C23: $B | D23: 1.482 | E23: 1.257 | F23: 1.059 | G23: 0.97 | H23: 0.705 | I23: 0.736
A24: V | B24: 自由現金流 FCF | C24: $B | D24: =D22-D23 -> 21.577 | E24: =E22-E23 -> 18.693 | F24: =F22-F23 -> 19.696 | G24: =G22-G23 -> 17.879 | H24: =H22-H23 -> 14.522 | I24: =I22-I23 -> 9.704
A25: V | B25: 總資產 / 總負債 FY25 | C25: $B | D25: 99.627 | E25: 61.718 | F25: 負債/資產 | G25: =E25/D25 -> 0.6194907
A26: NEE | B26: 營業收入 Revenue | C26: $B | D26: 27.412 | E26: 24.753 | F26: 28.114 | G26: 20.956 | H26: 17.069 | I26: 17.997 | J26: =IFERROR((D26/I26)^(1/5)-1,"n/m") -> 0.087797663
A27: NEE | B27: 淨利潤 Net income | C27: $B | D27: 6.835 | E27: 6.946 | F27: 7.31 | G27: 4.147 | H27: 3.573 | I27: 2.919
A28: NEE | B28: 每股收益 EPS | C28: $ | D28: 3.3 | E28: 3.37 | F28: 3.6 | G28: 2.1 | H28: 1.81 | I28: 1.48 | J28: =IFERROR((D28/I28)^(1/5)-1,"n/m") -> 0.17395228
A29: NEE | B29: ROE | C29: % | D29: 0.1306 | E29: 0.1424 | F29: 0.1686 | G29: 0.1085 | H29: 0.0969 | I29: 0.0794 | J29: =AVERAGE(D29:H29) -> 0.1294
A30: NEE | B30: 經營現金流 OCF | C30: $B | D30: 12.485 | E30: 13.26 | F30: 11.301 | G30: 8.262 | H30: 7.553 | I30: 7.983
A31: NEE | B31: 總資產 / 總負債 FY25 | C31: $B | D31: 212.721 | E31: 146.242 | F31: 負債/資產 | G31: =E31/D31 -> 0.68748267
A32: CEG | B32: 營業收入 Revenue | C32: $B | D32: 25.533 | E32: 23.568 | F32: 24.918 | G32: 24.44 | H32: 19.649 | I32: 17.603 | J32: =IFERROR((D32/I32)^(1/5)-1,"n/m") -> 0.077216585
A33: CEG | B33: 淨利潤 Net income | C33: $B | D33: 2.319 | E33: 3.749 | F33: 1.623 | G33: -0.16 | H33: -0.205 | I33: 0.589
A34: CEG | B34: 每股收益 EPS | C34: $ | D34: 7.4 | E34: 11.89 | F34: 5.01 | G34: -0.49 | J34: =IFERROR((D34/I34)^(1/5)-1,"n/m") -> n/m
A35: CEG | B35: ROE | C35: % | D35: 0.1675 | E35: 0.3112 | F35: 0.1479 | G35: -0.0144 | H35: -0.0174 | I35: 0.0455 | J35: =AVERAGE(D35:H35) -> 0.11896
A36: CEG | B36: 經營現金流 OCF | C36: $B | D36: 4.237 | E36: -2.464 | F36: -5.301 | G36: -2.353 | H36: -1.338 | I36: 0.584
A37: CEG | B37: 總資產 / 總負債 FY25 | C37: $B | D37: 57.249 | E37: 42.396 | F37: 負債/資產 | G37: =E37/D37 -> 0.74055442
A38: SO | B38: 營業收入 Revenue | C38: $B | D38: 29.553 | E38: 26.724 | F38: 25.253 | G38: 29.279 | H38: 23.113 | I38: 20.375 | J38: =IFERROR((D38/I38)^(1/5)-1,"n/m") -> 0.077211029
A39: SO | B39: 淨利潤 Net income | C39: $B | D39: 4.341 | E39: 4.401 | F39: 3.976 | G39: 3.524 | H39: 2.393 | I39: 3.119
A40: SO | B40: 每股收益 EPS | C40: $ | D40: 3.92 | E40: 3.99 | F40: 3.62 | G40: 3.26 | H40: 2.24 | I40: 2.93 | J40: =IFERROR((D40/I40)^(1/5)-1,"n/m") -> 0.059945876
A41: SO | B41: ROE | C41: % | D41: 0.1254 | E41: 0.1361 | F41: 0.1286 | G41: 0.1209 | H41: 0.0857 | I41: 0.1124 | J41: =AVERAGE(D41:H41) -> 0.11934
...

Sheet Valuation
A1: 多方法估值 & 反向 DCF
A2: A1=歷史中位倍數；A2=同業/目標倍數；B=兩階段 DCF/DDM（每股現金流 CF1 第 1–5 年按 g1 增長，之後按 gT 永續）；C=分析師共識目標價。黃底=全局假設。
A4: 全局假設（可調，全表重算）
A5: 無風險利率 rf（=Macro 10Y） | D5: =Macro!C8 -> 0.046
A6: 股權風險溢價 ERP | D6: 0.045
A7: 權重：A1 歷史倍數 | D7: 0.25
A8: 權重：A2 同業倍數 | D8: 0.15
A9: 權重：B 內在價值 | D9: 0.4
A10: 權重：C 共識目標 | D10: 0.2
A11: 低估門檻（安全邊際 ≥） | D11: 0.15
A12: 高估門檻（安全邊際 ≤） | D12: -0.1
A13: 權重合計 | D13: =SUM(D7:D10) -> 1
A15: Ticker | B15: A1 指標 | C15: A1 數值 | D15: 當前倍數 | E15: 歷史中位 | F15: A1 價值 | G15: A2 指標 | H15: A2 數值 | I15: 目標倍數 | J15: A2 價值 | K15: B 方法 | L15: B 基數 (Fwd) | M15: 轉換/派息率 | N15: CF1 ($) | O15: Beta | P15: r | Q15: g1 (1–5年) | R15: gT | S15: 每股調整 | T15: B 價值 | U15: C 共識目標 | V15: 加權內在價值 | W15: 股價 | X15: 安全邊際 | Y15: 估值判定 | Z15: 反向DCF 隱含永續g | AA15: 隱含g − gT | AB15: 方法備註
A16: BRK.B | B16: BVPS | C16: =Comps!E5/Comps!K5 -> 346.05369 | D16: =W16/C16 -> 1.49 | E16: =Comps!V5 -> 1.46 | F16: =C16*E16 -> 505.23839 | G16: P/B 行業 | H16: =C16 -> 346.05369 | I16: 1.48 | J16: =H16*I16 -> 512.15946 | K16: 營運EPS DCF | L16: =Comps!I5 -> 22.163 | M16: 1 | N16: =L16*M16 -> 22.163 | O16: 0.85 | P16: =$D$5+O16*$D$6 -> 0.08425 | Q16: 0.06 | R16: 0.03 | S16: 77.8 | T16: =IF(ABS(P16-Q16)<0.0001,N16*5/(1+P16),N16/(P16-Q16)*(1-((1+Q16)/(1+P16))^5))+N16*(1+Q16)^4*(1+R16)/(P16-R16)/(1+P16)^5+S16 -> 530.05496 | U16: 547.67 | V16: =F16*$D$7+J16*$D$8+T16*$D$9+U16*$D$10 -> 524.6895 | W16: =Comps!E5 -> 515.62 | X16: =V16/W16-1 -> 0.017589508 | Y16: =IF(X16>=$D$11,"低估",IF(X16<=$D$12,"高估","合理")) -> 合理 | Z16: =P16-N16*(1+Q16)/W16 -> 0.038687803 | AA16: =Z16-R16 -> 0.008687803 | AB16: A1/A2 用 P/B 區間；B=2027E 營運 EPS 兩階段 DCF + 超額現金每股 $77.8（($3,655億−$300億回購底線)×50%折讓÷21.57億股）
A17: JPM | B17: EPS TTM | C17: =Comps!E6/Comps!H6 -> 23.938893 | D17: =W17/C17 -> 13.91 | E17: =Comps!V6 -> 13.07 | F17: =C17*E17 -> 312.88133 | G17: EPS TTM | H17: =C17 -> 23.938893 | I17: 11.99 | J17: =H17*I17 -> 287.02733 | K17: 可分配盈利 DCF | L17: =Comps!I6 -> 24.46 | M17: 0.714 | N17: =L17*M17 -> 17.46444 | O17: 1.1 | P17: =$D$5+O17*$D$6 -> 0.0955 | Q17: 0.05 | R17: 0.035 | S17: 0 | T17: =IF(ABS(P17-Q17)<0.0001,N17*5/(1+P17),N17/(P17-Q17)*(1-((1+Q17)/(1+P17))^5))+N17*(1+Q17)^4*(1+R17)/(P17-R17)/(1+P17)^5+S17 -> 303.52067 | U17: 372.68 | V17: =F17*$D$7+J17*$D$8+T17*$D$9+U17*$D$10 -> 317.2187 | W17: =Comps!E6 -> 332.99 | X17: =V17/W17-1 -> -0.04736269 | Y17: =IF(X17>=$D$11,"低估",IF(X17<=$D$12,"高估","合理")) -> 合理 | Z17: =P17-N17*(1+Q17)/W17 -> 0.040430292 | AA17: =Z17-R17 -> 0.0054302922 | AB17: 轉換率=1−g/ROE=1−5%/17.5%（留存支持增長）；等同合理 P/B 框架。A2 用行業中位 P/E 11.99x
A18: V | B18: EPS TTM | C18: =Comps!E7/Comps!H7 -> 11.641498 | D18: =W18/C18 -> 33.11 | E18: =Comps!V7 -> 31.33 | F18: =C18*E18 -> 364.72813 | G18: EPS TTM | H18: =C18 -> 11.641498 | I18: 31.75 | J18: =H18*I18 -> 369.61756 | K18: FCF DCF | L18: =Comps!I7 -> 14.493 | M18: 1 | N18: =L18*M18 -> 14.493 | O18: 0.95 | P18: =$D$5+O18*$D$6 -> 0.08875 | Q18: 0.11 | R18: 0.04 | S18: 0 | T18: =IF(ABS(P18-Q18)<0.0001,N18*5/(1+P18),N18/(P18-Q18)*(1-((1+Q18)/(1+P18))^5))+N18*(1+Q18)^4*(1+R18)/(P18-R18)/(1+P18)^5+S18 -> 376.01631 | U18: 419.63 | V18: =F18*$D$7+J18*$D$8+T18*$D$9+U18*$D$10 -> 380.95719 | W18: =Comps!E7 -> 385.45 | X18: =V18/W18-1 -> -0.011656008 | Y18: =IF(X18>=$D$11,"低估",IF(X18<=$D$12,"高估","合理")) -> 合理 | Z18: =P18-N18*(1+Q18)/W18 -> 0.04701377 | AA18: =Z18-R18 -> 0.0070137696 | AB18: FCF≈淨利（轉換率 >100%）；A2 目標倍數取 MA 當前 P/E 31.75x（行業中位 14x 無可比性）
A19: NEE | B19: EPS TTM | C19: =Comps!E8/Comps!H8 -> 4.4573733 | D19: =W19/C19 -> 17.36 | E19: =Comps!V8 -> 25.22 | F19: =C19*E19 -> 112.41495 | G19: EPS TTM | H19: =C19 -> 4.4573733 | I19: 18.73 | J19: =H19*I19 -> 83.486601 | K19: DDM | L19: =Comps!I8 -> 4.155 | M19: 0.62 | N19: =L19*M19 -> 2.5761 | O19: 0.8 | P19: =$D$5+O19*$D$6 -> 0.082 | Q19: 0.065 | R19: 0.04 | S19: 0 | T19: =IF(ABS(P19-Q19)<0.0001,N19*5/(1+P19),N19/(P19-Q19)*(1-((1+Q19)/(1+P19))^5))+N19*(1+Q19)^4*(1+R19)/(P19-R19)/(1+P19)^5+S19 -> 66.872246 | U19: 97.05 | V19: =F19*$D$7+J19*$D$8+T19*$D$9+U19*$D$10 -> 86.785627 | W19: =Comps!E8 -> 77.38 | X19: =V19/W19-1 -> 0.12155114 | Y19: =IF(X19>=$D$11,"低估",IF(X19<=$D$12,"高估","合理")) -> 合理 | Z19: =P19-N19*(1+Q19)/W19 -> 0.046544501 | AA19: =Z19-R19 -> 0.0065445012 | AB19: DDM：CF1=Fwd EPS×派息率 62%（≈當前 DPS $2.44×1.06）；5Y 中位 25x 含零利率時期，偏高
A20: CEG | B20: EPS TTM | C20: =Comps!E9/Comps!H9 -> 9.7791995 | D20: =W20/C20 -> 30.48 | E20: =Comps!V9 -> 28.93 | F20: =C20*E20 -> 282.91224 | G20: EPS TTM | H20: =C20 -> 9.7791995 | I20: 26.74 | J20: =H20*I20 -> 261.49579 | K20: FCF DCF | L20: =Comps!I9 -> 12.041 | M20: 0.75 | N20: =L20*M20 -> 9.03075 | O20: 1.2 | P20: =$D$5+O20*$D$6 -> 0.1 | Q20: 0.1 | R20: 0.035 | S20: 0 | T20: =IF(ABS(P20-Q20)<0.0001,N20*5/(1+P20),N20/(P20-Q20)*(1-((1+Q20)/(1+P20))^5))+N20*(1+Q20)^4*(1+R20)/(P20-R20)/(1+P20)^5+S20 -> 171.77371 | U20: 341.53 | V20: =F20*$D$7+J20*$D$8+T20*$D$9+U20*$D$10 -> 246.96791 | W20: =Comps!E9 -> 298.07 | X20: =V20/W20-1 -> -0.17144325 | Y20: =IF(X20>=$D$11,"低估",IF(X20<=$D$12,"高估","合理")) -> 高估 | Z20: =P20-N20*(1+Q20)/W20 -> 0.066672845 | AA20: =Z20-R20 -> 0.031672845 | AB20: A2 目標倍數取 VST 26.7x（同為 IPP）；2026 調整後 EPS 指引 $11–12
A21: SO | B21: EPS TTM | C21: =Comps!E10/Comps!H10 -> 4.0493421 | D21: =W21/C21 -> 21.28 | E21: =Comps!V10 -> 22.49 | F21: =C21*E21 -> 91.069704 | G21: EPS TTM | H21: =C21 -> 4.0493421 | I21: 18.73 | J21: =H21*I21 -> 75.844178 | K21: DDM | L21: =Comps!I10 -> 4.633 | M21: 0.66 | N21: =L21*M21 -> 3.05778 | O21: 0.75 | P21: =$D$5+O21*$D$6 -> 0.07975 | Q21: 0.07 | R21: 0.04 | S21: 0 | T21: =IF(ABS(P21-Q21)<0.0001,N21*5/(1+P21),N21/(P21-Q21)*(1-((1+Q21)/(1+P21))^5))+N21*(1+Q21)^4*(1+R21)/(P21-R21)/(1+P21)^5+S21 -> 85.359414 | U21: 98.13 | V21: =F21*$D$7+J21*$D$8+T21*$D$9+U21*$D$10 -> 87.913818 | W21: =Comps!E10 -> 86.17 | X21: =V21/W21-1 -> 0.020236951 | Y21: =IF(X21>=$D$11,"低估",IF(X21<=$D$12,"高估","合理")) -> 合理 | Z21: =P21-N21*(1+Q21)/W21 -> 0.041780584 | AA21: =Z21-R21 -> 0.0017805837 | AB21: DDM：派息率 66%（DPS≈$3.0）；管理層指引 2028 前 EPS 增速 8–9%（取 7% 保守）
A22: WELL | B22: BVPS | C22: =Comps!E11/Comps!K11 -> 64.42 | D22: =W22/C22 -> 3.5 | E22: =Comps!V11 -> 2.19 | F22: =C22*E22 -> 141.0798 | G22: FFO 2026E | H22: 6.4 | I22: 25 | J22: =H22*I22 -> 160 | K22: AFFO DCF | L22: =H22 -> 6.4 | M22: 0.9 | N22: =L22*M22 -> 5.76 | O22: 0.85 | P22: =$D$5+O22*$D$6 -> 0.08425 | Q22: 0.12 | R22: 0.04 | S22: 0 | T22: =IF(ABS(P22-Q22)<0.0001,N22*5/(1+P22),N22/(P22-Q22)*(1-((1+Q22)/(1+P22))^5))+N22*(1+Q22)^4*(1+R22)/(P22-R22)/(1+P22)^5+S22 -> 170.52922 | U22: 262.05 | V22: =F22*$D$7+J22*$D$8+T22*$D$9+U22*$D$10 -> 179.89164 | W22: =Comps!E11 -> 225.47 | X22: =V22/W22-1 -> -0.20214823 | Y22: =IF(X22>=$D$11,"低估",IF(X22<=$D$12,"高估","合理")) -> 高估 | Z22: =P22-N22*(1+Q22)/W22 -> 0.055637768 | AA22: =Z22-R22 -> 0.015637768 | AB22: A2/B 基數用 2026 正常化 FFO 指引中值 $6.40（8-K 7/27）；AFFO≈90% FFO；目標 P/FFO 25x 為分析師估計
A23: PLD | B23: BVPS | C23: =Comps!E12/Comps!K12 -> 57.551111 | D23: =W23/C23 -> 2.25 | E23: =Comps!V12 -> 2.11 | F23: =C23*E23 -> 121.43284 | G23: Core FFO 2026E | H23: 6.26 | I23: 22 | J23: =H23*I23 -> 137.72 | K23: AFFO DCF | L23: =H23 -> 6.26 | M23: 0.85 | N23: =L23*M23 -> 5.321 | O23: 1.05 | P23: =$D$5+O23*$D$6 -> 0.09325 | Q23: 0.07 | R23: 0.035 | S23: 0 | T23: =IF(ABS(P23-Q23)<0.0001,N23*5/(1+P23),N23/(P23-Q23)*(1-((1+Q23)/(1+P23))^5))+N23*(1+Q23)^4*(1+R23)/(P23-R23)/(1+P23)^5+S23 -> 102.67758 | U23: 158.23 | V23: =F23*$D$7+J23*$D$8+T23*$D$9+U23*$D$10 -> 123.73324 | W23: =Comps!E12 -> 129.49 | X23: =V23/W23-1 -> -0.044457146 | Y23: =IF(X23>=$D$11,"低估",IF(X23<=$D$12,"高估","合理")) -> 合理 | Z23: =P23-N23*(1+Q23)/W23 -> 0.049281585 | AA23: =Z23-R23 -> 0.014281585 | AB23: Core FFO 指引中值 $6.26（$6.22–6.30）；AFFO≈85%；目標 P/FFO 22x（物流 REIT 歷史中樞，估計）
A24: EQIX | B24: BVPS | C24: =Comps!E13/Comps!K13 -> 145.74716 | D24: =W24/C24 -> 7.04 | E24: =Comps!V13 -> 5.99 | F24: =C24*E24 -> 873.02548 | G24: AFFO 2026E | H24: 42.99 | I24: 24 | J24: =H24*I24 -> 1031.76 | K24: AFFO DCF | L24: =H24 -> 42.99 | M24: 1 | N24: =L24*M24 -> 42.99 | O24: 0.9 | P24: =$D$5+O24*$D$6 -> 0.0865 | Q24: 0.09 | R24: 0.04 | S24: 0 | T24: =IF(ABS(P24-Q24)<0.0001,N24*5/(1+P24),N24/(P24-Q24)*(1-((1+Q24)/(1+P24))^5))+N24*(1+Q24)^4*(1+R24)/(P24-R24)/(1+P24)^5+S24 -> 1095.5227 | U24: 1234.19 | V24: =F24*$D$7+J24*$D$8+T24*$D$9+U24*$D$10 -> 1058.0674 | W24: =Comps!E13 -> 1026.06 | X24: =V24/W24-1 -> 0.031194509 | Y24: =IF(X24>=$D$11,"低估",IF(X24<=$D$12,"高估","合理")) -> 合理 | Z24: =P24-N24*(1+Q24)/W24 -> 0.040831033 | AA24: =Z24-R24 -> 0.00083103327 | AB24: AFFO 指引中值 $42.99（$42.69–43.29）；目標 P/AFFO 24x（估計）
A25: LIN | B25: EPS TTM | C25: =Comps!E14/Comps!H14 -> 15.715724 | D25: =W25/C25 -> 30.78 | E25: =Comps!V14 -> 33.68 | F25: =C25*E25 -> 529.3056 | G25: EPS TTM | H25: =C25 -> 15.715724 | I25: 29.45 | J25: =H25*I25 -> 462.82809 | K25: FCF DCF | L25: =Comps!I14 -> 18.74 | M25: 0.85 | N25: =L25*M25 -> 15.929 | O25: 0.9 | P25: =$D$5+O25*$D$6 -> 0.0865 | Q25: 0.08 | R25: 0.035 | S25: 0 | T25: =IF(ABS(P25-Q25)<0.0001,N25*5/(1+P25),N25/(P25-Q25)*(1-((1+Q25)/(1+P25))^5))+N25*(1+Q25)^4*(1+R25)/(P25-R25)/(1+P25)^5+S25 -> 360.08473 | U25: 543.04 | V25: =F25*$D$7+J25*$D$8+T25*$D$9+U25*$D$10 -> 454.39251 | W25: =Comps!E14 -> 483.73 | X25: =V25/W25-1 -> -0.060648489 | Y25: =IF(X25>=$D$11,"低估",IF(X25<=$D$12,"高估","合理")) -> 合理 | Z25: =P25-N25*(1+Q25)/W25 -> 0.050936111 | AA25: =Z25-R25 -> 0.015936111 | AB25: 2026 調整後 EPS 指引 $17.70–17.90（+8–9%）；FCF 轉換率 85%（增長型資本開支）
A26: NEM | B26: EPS TTM | C26: =Comps!E15/Comps!H15 -> 8.1606648 | D26: =W26/C26 -> 14.44 | E26: =Comps!V15 -> 14.92 | F26: =C26*E26 -> 121.75712 | G26: EPS TTM | H26: =C26 -> 8.1606648 | I26: 8.53 | J26: =H26*I26 -> 69.610471 | K26: 正常化 DCF | L26: =Comps!I15 -> 8.99 | M26: 0.9 | N26: =L26*M26 -> 8.091 | O26: 0.9 | P26: =$D$5+O26*$D$6 -> 0.0865 | Q26: -0.08 | R26: 0.02 | S26: 0 | T26: =IF(ABS(P26-Q26)<0.0001,N26*5/(1+P26),N26/(P26-Q26)*(1-((1+Q26)/(1+P26))^5))+N26*(1+Q26)^4*(1+R26)/(P26-R26)/(1+P26)^5+S26 -> 86.160919 | U26: 137.33 | V26: =F26*$D$7+J26*$D$8+T26*$D$9+U26*$D$10 -> 102.81122 | W26: =Comps!E15 -> 117.84 | X26: =V26/W26-1 -> -0.12753549 | Y26: =IF(X26>=$D$11,"低估",IF(X26<=$D$12,"高估","合理")) -> 高估 | Z26: =P26-N26*(1+Q26)/W26 -> 0.023331976 | AA26: =Z26-R26 -> 0.0033319756 | AB26: g1=−8% 反映金價由 ~$4,500 向中週期回歸假設；歷史區間僅 1 年（高金價期）
A27: FCX | B27: EPS TTM | C27: =Comps!E16/Comps!H16 -> 2.0446726 | D27: =W27/C27 -> 36.04 | E27: =Comps!V16 -> 32.55 | F27: =C27*E27 -> 66.554093 | G27: EPS TTM | H27: =C27 -> 2.0446726 | I27: 31.2 | J27: =H27*I27 -> 63.793785 | K27: 正常化 DCF | L27: =Comps!I16 -> 3.8 | M27: 0.7 | N27: =L27*M27 -> 2.66 | O27: 1.5 | P27: =$D$5+O27*$D$6 -> 0.1135 | Q27: 0.04 | R27: 0.025 | S27: 0 | T27: =IF(ABS(P27-Q27)<0.0001,N27*5/(1+P27),N27/(P27-Q27)*(1-((1+Q27)/(1+P27))^5))+N27*(1+Q27)^4*(1+R27)/(P27-R27)/(1+P27)^5+S27 -> 31.522649 | U27: 77.55 | V27: =F27*$D$7+J27*$D$8+T27*$D$9+U27*$D$10 -> 54.326651 | W27: =Comps!E16 -> 73.69 | X27: =V27/W27-1 -> -0.26276767 | Y27: =IF(X27>=$D$11,"低估",IF(X27<=$D$12,"高估","合理")) -> 高估 | Z27: =P27-N27*(1+Q27)/W27 -> 0.07595895 | AA27: =Z27-R27 -> 0.05095895 | AB27: Grasberg 2027 年底恢復滿產支撐量增，但銅價 $6.5/lb 處高位；Beta 1.5
A29: 讀表說明
A30: • 反向 DCF：在當前股價下，市場隱含的永續增長率 g = r − CF2/P（CF2 = CF1×(1+g1)，單階段 Gordon 反解）。隱含 g 遠高於 gT（第 AA 欄 > +1.5%）代表市場已定價高增長，容錯空間小。
A31: • 共識目標價（C）只佔 20%：分析師目標價有樂觀與追漲偏差，僅作情緒參考。
A32: • REIT 的 B 值以 AFFO 為現金流基數；公用事業用 DDM（股息為股東實得現金，重資本開支令 FCF 為負）；銀行用可分配盈利（=EPS×(1−g/ROE)）。
A33: • 所有 g1/gT/轉換率/Beta/目標倍數為分析師假設（藍字黃底），可直接修改測試敏感度。Beta 為 Blume 調整後估計值（0.67×原始+0.33）；公用事業原始 Beta 偏低會低估其利率風險。
A35: 敏感度：LIN 內在價值（B）對 折現率 r × 第一階段增長 g1（gT 取表內值）
A36: r ↓ / g1 → | B36: 0.06 | C36: 0.07 | D36: 0.08 | E36: 0.09 | F36: 0.1 | H36: 現價
A37: 0.075 | B37: =IF(ABS($A37-B$36)<0.0001,$N$25*5/(1+$A37),$N$25/($A37-B$36)*(1-((1+B$36)/(1+$A37))^5))+$N$25*(1+B$36)^4*(1+$R$25)/($A37-$R$25)/(1+$A37)^5 -> 434.50103 | C37: =IF(ABS($A37-C$36)<0.0001,$N$25*5/(1+$A37),$N$25/($A37-C$36)*(1-((1+C$36)/(1+$A37))^5))+$N$25*(1+C$36)^4*(1+$R$25)/($A37-$R$25)/(1+$A37)^5 -> 449.72615 | D37: =IF(ABS($A37-D$36)<0.0001,$N$25*5/(1+$A37),$N$25/($A37-D$36)*(1-((1+D$36)/(1+$A37))^5))+$N$25*(1+D$36)^4*(1+$R$25)/($A37-$R$25)/(1+$A37)^5 -> 465.37119 | E37: =IF(ABS($A37-E$36)<0.0001,$N$25*5/(1+$A37),$N$25/($A37-E$36)*(1-((1+E$36)/(1+$A37))^5))+$N$25*(1+E$36)^4*(1+$R$25)/($A37-$R$25)/(1+$A37)^5 -> 481.44389 | F37: =IF(ABS($A37-F$36)<0.0001,$N$25*5/(1+$A37),$N$25/($A37-F$36)*(1-((1+F$36)/(1+$A37))^5))+$N$25*(1+F$36)^4*(1+$R$25)/($A37-$R$25)/(1+$A37)^5 -> 497.9521 | H37: =W25 -> 483.73
A38: 0.08 | B38: =IF(ABS($A38-B$36)<0.0001,$N$25*5/(1+$A38),$N$25/($A38-B$36)*(1-((1+B$36)/(1+$A38))^5))+$N$25*(1+B$36)^4*(1+$R$25)/($A38-$R$25)/(1+$A38)^5 -> 385.85425 | C38: =IF(ABS($A38-C$36)<0.0001,$N$25*5/(1+$A38),$N$25/($A38-C$36)*(1-((1+C$36)/(1+$A38))^5))+$N$25*(1+C$36)^4*(1+$R$25)/($A38-$R$25)/(1+$A38)^5 -> 399.23041 | D38: =IF(ABS($A38-D$36)<0.0001,$N$25*5/(1+$A38),$N$25/($A38-D$36)*(1-((1+D$36)/(1+$A38))^5))+$N$25*(1+D$36)^4*(1+$R$25)/($A38-$R$25)/(1+$A38)^5 -> 412.97407 | E38: =IF(ABS($A38-E$36)<0.0001,$N$25*5/(1+$A38),$N$25/($A38-E$36)*(1-((1+E$36)/(1+$A38))^5))+$N$25*(1+E$36)^4*(1+$R$25)/($A38-$R$25)/(1+$A38)^5 -> 427.09204 | F38: =IF(ABS($A38-F$36)<0.0001,$N$25*5/(1+$A38),$N$25/($A38-F$36)*(1-((1+F$36)/(1+$A38))^5))+$N$25*(1+F$36)^4*(1+$R$25)/($A38-$R$25)/(1+$A38)^5 -> 441.59114
A39: 0.085 | B39: =IF(ABS($A39-B$36)<0.0001,$N$25*5/(1+$A39),$N$25/($A39-B$36)*(1-((1+B$36)/(1+$A39))^5))+$N$25*(1+B$36)^4*(1+$R$25)/($A39-$R$25)/(1+$A39)^5 -> 346.94289 | C39: =IF(ABS($A39-C$36)<0.0001,$N$25*5/(1+$A39),$N$25/($A39-C$36)*(1-((1+C$36)/(1+$A39))^5))+$N$25*(1+C$36)^4*(1+$R$25)/($A39-$R$25)/(1+$A39)^5 -> 358.84247 | D39: =IF(ABS($A39-D$36)<0.0001,$N$25*5/(1+$A39),$N$25/($A39-D$36)*(1-((1+D$36)/(1+$A39))^5))+$N$25*(1+D$36)^4*(1+$R$25)/($A39-$R$25)/(1+$A39)^5 -> 371.06777 | E39: =IF(ABS($A39-E$36)<0.0001,$N$25*5/(1+$A39),$N$25/($A39-E$36)*(1-((1+E$36)/(1+$A39))^5))+$N$25*(1+E$36)^4*(1+$R$25)/($A39-$R$25)/(1+$A39)^5 -> 383.62476 | F39: =IF(ABS($A39-F$36)<0.0001,$N$25*5/(1+$A39),$N$25/($A39-F$36)*(1-((1+F$36)/(1+$A39))^5))+$N$25*(1+F$36)^4*(1+$R$25)/($A39-$R$25)/(1+$A39)^5 -> 396.51952
A40: 0.09 | B40: =IF(ABS($A40-B$36)<0.0001,$N$25*5/(1+$A40),$N$25/($A40-B$36)*(1-((1+B$36)/(1+$A40))^5))+$N$25*(1+B$36)^4*(1+$R$25)/($A40-$R$25)/(1+$A40)^5 -> 315.1117 | C40: =IF(ABS($A40-C$36)<0.0001,$N$25*5/(1+$A40),$N$25/($A40-C$36)*(1-((1+C$36)/(1+$A40))^5))+$N$25*(1+C$36)^4*(1+$R$25)/($A40-$R$25)/(1+$A40)^5 -> 325.8055 | D40: =IF(ABS($A40-D$36)<0.0001,$N$25*5/(1+$A40),$N$25/($A40-D$36)*(1-((1+D$36)/(1+$A40))^5))+$N$25*(1+D$36)^4*(1+$R$25)/($A40-$R$25)/(1+$A40)^5 -> 336.79089 | E40: =IF(ABS($A40-E$36)<0.0001,$N$25*5/(1+$A40),$N$25/($A40-E$36)*(1-((1+E$36)/(1+$A40))^5))+$N$25*(1+E$36)^4*(1+$R$25)/($A40-$R$25)/(1+$A40)^5 -> 348.07323 | F40: =IF(ABS($A40-F$36)<0.0001,$N$25*5/(1+$A40),$N$25/($A40-F$36)*(1-((1+F$36)/(1+$A40))^5))+$N$25*(1+F$36)^4*(1+$R$25)/($A40-$R$25)/(1+$A40)^5 -> 359.65793
A41: 0.095 | B41: =IF(ABS($A41-B$36)<0.0001,$N$25*5/(1+$A41),$N$25/($A41-B$36)*(1-((1+B$36)/(1+$A41))^5))+$N$25*(1+B$36)^4*(1+$R$25)/($A41-$R$25)/(1+$A41)^5 -> 288.59052 | C41: =IF(ABS($A41-C$36)<0.0001,$N$25*5/(1+$A41),$N$25/($A41-C$36)*(1-((1+C$36)/(1+$A41))^5))+$N$25*(1+C$36)^4*(1+$R$25)/($A41-$R$25)/(1+$A41)^5 -> 298.28157 | D41: =IF(ABS($A41-D$36)<0.0001,$N$25*5/(1+$A41),$N$25/($A41-D$36)*(1-((1+D$36)/(1+$A41))^5))+$N$25*(1+D$36)^4*(1+$R$25)/($A41-$R$25)/(1+$A41)^5 -> 308.23586 | E41: =IF(ABS($A41-E$36)<0.0001,$N$25*5/(1+$A41),$N$25/($A41-E$36)*(1-((1+E$36)/(1+$A41))^5))+$N$25*(1+E$36)^4*(1+$R$25)/($A41-$R$25)/(1+$A41)^5 -> 318.45822 | F41: =IF(ABS($A41-F$36)<0.0001,$N$25*5/(1+$A41),$N$25/($A41-F$36)*(1-((1+F$36)/(1+$A41))^5))+$N$25*(1+F$36)^4*(1+$R$25)/($A41-$R$25)/(1+$A41)^5 -> 328.95355

Sheet Scorecard
A1: 巴菲特準則評分卡（質量）+ 估值分
A2: 0–5 分；藍字=分析師判斷（理由見右欄），黑字=公式（宏觀韌性連結 Macro，估值分由安全邊際與 5 年預期回報計算）。
A4: 權重（質量分內部，可調）
B5: 業務易懂(能力圈) | C5: 護城河寬度 | D5: 長期 ROE/ROIC 質量 | E5: 資產負債表穩健 | F5: 管理層（誠信+資本配置） | G5: 宏觀韌性
A6: 權重 | B6: 0.1 | C6: 0.3 | D6: 0.15 | E6: 0.1 | F6: 0.25 | G6: 0.1 | H6: =SUM(B6:G6) -> 1
A7: 綜合分 = 質量分 × 質量權重 + 估值分 × (1−質量權重)；質量權重： | I7: 0.6
A9: Ticker | B9: 業務易懂(能力圈) | C9: 護城河寬度 | D9: 長期 ROE/ROIC 質量 | E9: 資產負債表穩健 | F9: 管理層（誠信+資本配置） | G9: 宏觀韌性 | H9: 質量分 (0–100) | I9: 安全邊際 | J9: 5Y 預期年化 | K9: 估值分 (0–100) | L9: 綜合分 | M9: 排名 | N9: 護城河類型 / 寬度 | O9: 管理層評估 | P9: 巴菲特視角
A10: BRK.B | B10: 4 | C10: 5 | D10: 3 | E10: 5 | F10: 4 | G10: =Macro!I24 -> 3 | H10: =SUMPRODUCT(B10:G10,$B$6:$G$6)/5*100 -> 83 | I10: =Valuation!X16 -> 0.017589508 | J10: =Picks!N6 -> 0.075615552 | K10: =ROUND(0.5*MAX(0,MIN(100,(I10+0.3)/0.6*100))+0.5*MAX(0,MIN(100,(J10-0.02)/0.1*100)),0) -> 54 | L10: =ROUND(H10*$I$7+K10*(1-$I$7),1) -> 71.4 | M10: =RANK(L10,$L$10:$L$21) -> 4 | N10: 寬：低成本浮存金、永久資本、分散化現金流、「首選買家」聲譽 | O10: Greg Abel 2026/1 接任 CEO；Q2 營運盈利 +16% 至 $129.8 億；回購重啟（Q2 $45 億，判斷內在價值高於市價）；$100 億投資 Alphabet、$68 億收購 Taylor Morrison。後巴菲特時代資本配置能力待驗證 | P10: 巴菲特親手打造；P/B 1.49 接近其歷史回購區間；$3,655 億現金在加息期是期權，不是負擔
A11: JPM | B11: 4 | C11: 4 | D11: 4 | E11: 3 | F11: 5 | G11: =Macro!I25 -> 3 | H11: =SUMPRODUCT(B11:G11,$B$6:$G$6)/5*100 -> 81 | I11: =Valuation!X17 -> -0.04736269 | J11: =Picks!N7 -> 0.078674857 | K11: =ROUND(0.5*MAX(0,MIN(100,(I11+0.3)/0.6*100))+0.5*MAX(0,MIN(100,(J11-0.02)/0.1*100)),0) -> 50 | L11: =ROUND(H11*$I$7+K11*(1-$I$7),1) -> 68.6 | M11: =RANK(L11,$L$10:$L$21) -> 5 | N11: 寬：規模、低成本存款、全業務線、科技投入 | O11: Jamie Dimon 2005 年起任 CEO，ROE 16–18%、堡壘式資產負債表；2026 NII 指引上調至 ~$1,055 億；接班「數年內」、兩位聯席總裁 | P11: 巴菲特曾稱 Dimon 為最佳銀行家；但 P/B 2.5x 高於行業 1.57x，價格已反映質量
A12: V | B12: 5 | C12: 5 | D12: 5 | E12: 4 | F12: 4 | G12: =Macro!I26 -> 2 | H12: =SUMPRODUCT(B12:G12,$B$6:$G$6)/5*100 -> 87 | I12: =Valuation!X18 -> -0.011656008 | J12: =Picks!N8 -> 0.10334952 | K12: =ROUND(0.5*MAX(0,MIN(100,(I12+0.3)/0.6*100))+0.5*MAX(0,MIN(100,(J12-0.02)/0.1*100)),0) -> 66 | L12: =ROUND(H12*$I$7+K12*(1-$I$7),1) -> 78.6 | M12: =RANK(L12,$L$10:$L$21) -> 2 | N12: 極寬：雙邊網絡效應 + 雙寡頭；毛利 97.8%、ROE 53% | O12: Ryan McInerney 2023 年起；每季回饋股東 ~$61 億（回購+股息）；需處理 CCCA、DOJ 反壟斷、交換費訴訟（每季撥備 $6–10 億） | P12: 巴菲特持有 V/MA；典型「以合理價格買入卓越公司」，但 33x TTM 不便宜
A13: NEE | B13: 3 | C13: 3 | D13: 3 | E13: 2 | F13: 3 | G13: =Macro!I27 -> 1 | H13: =SUMPRODUCT(B13:G13,$B$6:$G$6)/5*100 -> 54 | I13: =Valuation!X19 -> 0.12155114 | J13: =Picks!N9 -> 0.11687106 | K13: =ROUND(0.5*MAX(0,MIN(100,(I13+0.3)/0.6*100))+0.5*MAX(0,MIN(100,(J13-0.02)/0.1*100)),0) -> 84 | L13: =ROUND(H13*$I$7+K13*(1-$I$7),1) -> 66 | M13: =RANK(L13,$L$10:$L$21) -> 7 | N13: 窄：FPL 受監管壟斷 + 再生能源開發規模 | O13: John Ketchum 2022 年起；2026/5 宣布 $668 億收購 Dominion，溢價受質疑、股價半年 −17%；FCF 長期為負依賴融資 | P13: 巴菲特經 BHE 持有公用事業，但偏好低槓桿；NEE 估值處 5 年低位（比 87% 時間便宜）是逆向機會而非質量標的
A14: CEG | B14: 3 | C14: 3 | D14: 3 | E14: 3 | F14: 3 | G14: =Macro!I28 -> 4 | H14: =SUMPRODUCT(B14:G14,$B$6:$G$6)/5*100 -> 62 | I14: =Valuation!X20 -> -0.17144325 | J14: =Picks!N10 -> 0.07995072 | K14: =ROUND(0.5*MAX(0,MIN(100,(I14+0.3)/0.6*100))+0.5*MAX(0,MIN(100,(J14-0.02)/0.1*100)),0) -> 41 | L14: =ROUND(H14*$I$7+K14*(1-$I$7),1) -> 53.6 | M14: =RANK(L14,$L$10:$L$21) -> 9 | N14: 窄–寬：核電機組不可複製 | O14: Joe Dominguez；Calpine 併購整合中；2026 指引 $11–12 低於預期、缺新超大規模 PPA | P14: 盈利受電價與合約時點驅動，可預測性不足
A15: SO | B15: 4 | C15: 3 | D15: 3 | E15: 2 | F15: 3 | G15: =Macro!I29 -> 4 | H15: =SUMPRODUCT(B15:G15,$B$6:$G$6)/5*100 -> 62 | I15: =Valuation!X21 -> 0.020236951 | J15: =Picks!N11 -> 0.10365641 | K15: =ROUND(0.5*MAX(0,MIN(100,(I15+0.3)/0.6*100))+0.5*MAX(0,MIN(100,(J15-0.02)/0.1*100)),0) -> 69 | L15: =ROUND(H15*$I$7+K15*(1-$I$7),1) -> 64.8 | M15: =RANK(L15,$L$10:$L$21) -> 8 | N15: 窄：東南部受監管壟斷 | O15: Chris Womack 2023 年起；Vogtle 3/4 超支延誤為歷史污點；$810 億資本計劃、17GW 大負荷合約 | P15: 業務易懂、股息穩，但高負債（負債/資產 75%）與監管風險
A16: WELL | B16: 3 | C16: 3 | D16: 2 | E16: 4 | F16: 4 | G16: =Macro!I30 -> 2 | H16: =SUMPRODUCT(B16:G16,$B$6:$G$6)/5*100 -> 62 | I16: =Valuation!X22 -> -0.20214823 | J16: =Picks!N12 -> 0.068976515 | K16: =ROUND(0.5*MAX(0,MIN(100,(I16+0.3)/0.6*100))+0.5*MAX(0,MIN(100,(J16-0.02)/0.1*100)),0) -> 33 | L16: =ROUND(H16*$I$7+K16*(1-$I$7),1) -> 50.4 | M16: =RANK(L16,$L$10:$L$21) -> 10 | N16: 窄：長者住宅營運平台 + 數據化管理 | O16: Shankh Mitra 2020 年起；FFO 指引上調至 $6.36–6.44、股息 +15%；資本配置出色 | P16: 好公司但 P/FFO 35x、P/B 處 5 年高位（僅比 8% 時間便宜），無安全邊際
A17: PLD | B17: 4 | C17: 4 | D17: 3 | E17: 4 | F17: 5 | G17: =Macro!I31 -> 3 | H17: =SUMPRODUCT(B17:G17,$B$6:$G$6)/5*100 -> 80 | I17: =Valuation!X23 -> -0.044457146 | J17: =Picks!N13 -> 0.10583606 | K17: =ROUND(0.5*MAX(0,MIN(100,(I17+0.3)/0.6*100))+0.5*MAX(0,MIN(100,(J17-0.02)/0.1*100)),0) -> 64 | L17: =ROUND(H17*$I$7+K17*(1-$I$7),1) -> 73.6 | M17: =RANK(L17,$L$10:$L$21) -> 3 | N17: 寬：全球物流網絡規模 + 客戶關係 + 低資本成本 | O17: Hamid Moghadam（創辦人，執行主席）/ Dan Letter（CEO）；Core FFO 指引上調至 $6.22–6.30；數據中心電力管線 5.8GW；擬收購 SEGRO 待觀察 | P17: 類似「收費公路」的物流地產；P/FFO 20.7x 處合理區間，股息 3.3%
A18: EQIX | B18: 3 | C18: 4 | D18: 3 | E18: 3 | F18: 3 | G18: =Macro!I32 -> 3 | H18: =SUMPRODUCT(B18:G18,$B$6:$G$6)/5*100 -> 66 | I18: =Valuation!X24 -> 0.031194509 | J18: =Picks!N14 -> 0.1016595 | K18: =ROUND(0.5*MAX(0,MIN(100,(I18+0.3)/0.6*100))+0.5*MAX(0,MIN(100,(J18-0.02)/0.1*100)),0) -> 68 | L18: =ROUND(H18*$I$7+K18*(1-$I$7),1) -> 66.8 | M18: =RANK(L18,$L$10:$L$21) -> 6 | N18: 寬：互聯生態網絡效應 | O18: Adaire Fox-Martin 2024 年起；AFFO 指引上調至 $42.69–43.29；2024 年遭沽空報告質疑 AFFO 口徑；資本開支 $50–60 億 | P18: 護城河強但資本密集、P/B 處 5 年高位
A19: LIN | B19: 5 | C19: 5 | D19: 4 | E19: 4 | F19: 5 | G19: =Macro!I33 -> 4 | H19: =SUMPRODUCT(B19:G19,$B$6:$G$6)/5*100 -> 93 | I19: =Valuation!X25 -> -0.060648489 | J19: =Picks!N15 -> 0.10780256 | K19: =ROUND(0.5*MAX(0,MIN(100,(I19+0.3)/0.6*100))+0.5*MAX(0,MIN(100,(J19-0.02)/0.1*100)),0) -> 64 | L19: =ROUND(H19*$I$7+K19*(1-$I$7),1) -> 81.4 | M19: =RANK(L19,$L$10:$L$21) -> 1 | N19: 寬：三寡頭 + 長約 + 區域密度 + 轉換成本 | O19: Sanjiv Lamba 2022 年起；EPS 指引 +8–9%、backlog $110 億；ROE 由 5% 升至 18%；紀律性回購 | P19: 最接近「工業版收費站」；P/E 處 5 年最低 9%（比 91% 時間便宜），質量+估值兼得
A20: NEM | B20: 3 | C20: 1 | D20: 2 | E20: 4 | F20: 3 | G20: =Macro!I34 -> 3 | H20: =SUMPRODUCT(B20:G20,$B$6:$G$6)/5*100 -> 47 | I20: =Valuation!X26 -> -0.12753549 | J20: =Picks!N16 -> -0.057931272 | K20: =ROUND(0.5*MAX(0,MIN(100,(I20+0.3)/0.6*100))+0.5*MAX(0,MIN(100,(J20-0.02)/0.1*100)),0) -> 14 | L20: =ROUND(H20*$I$7+K20*(1-$I$7),1) -> 33.8 | M20: =RANK(L20,$L$10:$L$21) -> 12 | N20: 無：價格接受者 | O20: Natascha Viljoen（2026 起任 CEO）；Q2 FCF 創紀錄 $22 億、淨現金 $34 億、$60 億回購；Newcrest 併購攤薄歷史 | P20: 巴菲特曾形容黃金「不產生任何東西」；盈利完全取決於金價
A21: FCX | B21: 3 | C21: 2 | D21: 3 | E21: 3 | F21: 3 | G21: =Macro!I35 -> 4 | H21: =SUMPRODUCT(B21:G21,$B$6:$G$6)/5*100 -> 56 | I21: =Valuation!X27 -> -0.26276767 | J21: =Picks!N17 -> 0.018073611 | K21: =ROUND(0.5*MAX(0,MIN(100,(I21+0.3)/0.6*100))+0.5*MAX(0,MIN(100,(J21-0.02)/0.1*100)),0) -> 3 | L21: =ROUND(H21*$I$7+K21*(1-$I$7),1) -> 34.8 | M21: =RANK(L21,$L$10:$L$21) -> 11 | N21: 窄：一級資產但無定價權 | O21: Kathleen Quirk 2024 年起；Grasberg 2025 年泥石流事故後產能 65%，2027 年底恢復；Q3 實現銅價 >$6.5/lb | P21: 週期性、資本密集；不符巴菲特偏好
A23: 估值分 = 50% × 安全邊際分（−30%→0 分，+30%→100 分）+ 50% × 5 年預期年化回報分（2%→0 分，12%→100 分）。
A25: 巴菲特選股邏輯（本評分卡的框架來源）
A26: 1. 能力圈：只買自己看得懂、10 年後大概率仍存在的業務（→ 業務易懂分）。
A27: 2. 持久競爭優勢（Moat）：「我們尋找被寬闊護城河保護的經濟城堡」（→ 權重最高 30%）。
A28: 3. 高且穩定的 ROE、低負債：不靠槓桿也能賺高回報（→ ROE 質量、資產負債表）。
A29: 4. 誠實能幹、以股東利益為先的管理層，資本配置能力決定長期複利（→ 25%）。
A30: 5. 安全邊際：「以合理價格買入卓越公司，勝過以低價買入平庸公司」（→ 估值分，佔綜合分 40%）。
A31: 6. 避開：需持續大量資本開支且無定價權的週期業務（礦業）；價格完全取決於商品的資產。

Sheet Picks
A1: 5 年期選股 — 預期回報、排序與組合
A2: 5Y 預期年化 = [(1+g)^5 × 退出倍數/買入倍數]^(1/5) − 1 + 股息率。g、退出倍數為分析師假設（黃底）；綜合分來自 Scorecard。
A3: 結論：5 年期首選 LIN、BRK.B、V、PLD、JPM 為核心，NEE 作逆向小倉位。核心特徵＝寬護城河 + 優秀管理層 + 估值不高於歷史中位；刻意迴避週期頂部（NEM/FCX/能源）與估值過高的好公司（WELL/EQIX）。
A5: Ticker | B5: 公司 | C5: 板塊 | D5: 股價 | E5: 倍數基數 | F5: 基數值 | G5: 買入倍數 | H5: 退出倍數 | I5: g (5年CAGR) | J5: 股息率 | K5: 倍數變化/年 | L5: 盈利貢獻/年 | M5: — | N5: 5Y 預期年化 | O5: 綜合分 | P5: 排名 | Q5: 建議 | R5: 組合權重 | S5: 買入理由（為什麼選它） | T5: 出場/判斷錯誤條件（Kill criteria）
A6: BRK.B | B6: Berkshire Hathaway | C6: 金融 | D6: =Comps!E5 -> 515.62 | E6: BVPS | F6: =Valuation!C16 -> 346.05369 | G6: =D6/F6 -> 1.49 | H6: 1.46 | I6: 0.08 | J6: =Comps!L5 -> 0 | K6: =(H6/G6)^(1/5)-1 -> -0.004059674 | L6: =I6 -> 0.08 | N6: =((1+I6)^5*H6/G6)^(1/5)-1+J6 -> 0.075615552 | O6: =Scorecard!L10 -> 71.4 | P6: =Scorecard!M10 -> 4 | Q6: 核心持有 | R6: 0.225 | S6: 質量最高、下行保護最強：$3,655 億現金在加息期賺取 ~4% 利息並等待危機中的收購機會；P/B 1.49 接近歷史回購區間，Abel 已用真金白銀回購（Q2 $45 億）；營運盈利 +16%。是組合的「壓艙石」。 | T6: 回購在 P/B<1.4 時停止（反映管理層不再認為便宜）；高價大型併購；保險承保結構性虧損；P/B>1.8 減持
A7: JPM | B7: JPMorgan Chase | C7: 金融 | D7: =Comps!E6 -> 332.99 | E7: Fwd EPS | F7: =Comps!I6 -> 24.46 | G7: =D7/F7 -> 13.613655 | H7: 13 | I7: 0.07 | J7: =Comps!L6 -> 0.0185 | K7: =(H7/G7)^(1/5)-1 -> -0.0091823765 | L7: =I7 -> 0.07 | N7: =((1+I7)^5*H7/G7)^(1/5)-1+J7 -> 0.078674857 | O7: =Scorecard!L11 -> 68.6 | P7: =Scorecard!M11 -> 5 | Q7: 核心持有（逢低加碼） | R7: 0.125 | S7: 美國最佳銀行：ROE 17–18%、CET1 14%+；加息擴大 NII（2026 指引 ~$1,055 億）；估值處 3 年中位附近，不貴不便宜，建議股價 <$300（≈2.25x P/B）時加碼。 | T7: CET1 < 12.5%；淨撇賬率 > 1.5%；接班混亂；P/TBV > 3x 減持
